Workbook

Sheet Week 1
A1: AMC | F1: Employee AweS.U.M. Report
A2: Woodinville Unit2449 (02449)
A3: 17640 138th Pl. NE
A4: Woodinville, Washington | F4: Business Date Range: 11/21/2025 to 11/27/2025
A5: 98072- | F5: Sort By Employee
A6: UNITED STATES
M7: Average | AC7: Team | AD7: UPT | AE7: n | AG7: Winner For the Week | AK7: Scoreboard
I8: UPT | M8: Transaction | W8: Chica | Y8: Average Tranaction | Z8: =(SUM(Y11:Y20)/SUM(X11:X20)) -> 2.6683203 | AC8: =W8 -> Chica | AD8: =Z8 -> 2.6683203 | AE8: =SUM(X11:X20) -> 1411 | AG8: 1st | AH8: =INDEX($AC$8:$AC$12, MATCH(LARGE($AD$8:$AD$12, 1), $AD$8:$AD$12, 0)) -> Freddy | AL8: Previous Week | AM8: Bonus Points (Individual) | AN8: Bonus Point Team Improvement | AO8: Earned Points | AP8: Total Points
G9: Theatre Average: | I9: 2.68 | O9: $25.32 | AC9: =W22 -> Bonnie | AD9: =Z22 -> 2.5670498 | AE9: =SUM(X25:X34) -> 522 | AG9: 2nd | AH9: =INDEX($AC$8:$AC$12, MATCH(LARGE($AD$8:$AD$12, 2), $AD$8:$AD$12, 0)) -> Balloon Boy | AK9: =W8 -> Chica | AM9: =AD28 -> 1 | AO9: =AH14 -> 1 | AP9: =SUM(AL9:AO9) -> 2
D10: # of Transactions | X10: # Transactions | Y10: # of Units Sold | Z10: UPT | AC10: =W36 -> Freddy | AD10: =Z36 -> 2.8501742 | AE10: =SUM(X39:X48) -> 574 | AG10: 3rd | AH10: =INDEX($AC$8:$AC$12, MATCH(LARGE($AD$8:$AD$12, 3), $AD$8:$AD$12, 0)) -> Chica | AK10: =W22 -> Bonnie | AM10: =AD41 -> 0 | AO10: =AH15 -> 0 | AP10: =SUM(AL10:AO10) -> 0
A11: Employee Name | G11: # of Units Sold | K11: Total Sales | P11: UPT | S11: Average Transaction | W11: Lopez, Ebony | X11: =VLOOKUP(W11,$A$12:$S$57, 4,FALSE) -> 85 | Y11: =VLOOKUP(W11,$A$12:$S$57, 8,FALSE) -> 236 | Z11: =VLOOKUP(W11,$A$12:$S$57, 16,FALSE) -> 2.78 | AC11: =W50 -> Balloon Boy | AD11: =Z50 -> 2.6995012 | AE11: =SUM(X53:X61) -> 802 | AK11: =W36 -> Freddy | AM11: =AD54 -> 2 | AO11: =AH16 -> 3 | AP11: =SUM(AL11:AO11) -> 5
A12: Admin, AMC | D12: 0 | H12: 0 | L12: 0 | P12: 0 | S12: 0 | W12: Allen, Wren | X12: =VLOOKUP(W12,$A$12:$S$57, 4,FALSE) -> 261 | Y12: =VLOOKUP(W12,$A$12:$S$57, 8,FALSE) -> 697 | Z12: =VLOOKUP(W12,$A$12:$S$57, 16,FALSE) -> 2.67 | AC12: =W63 -> Foxy | AD12: =Z63 -> 2.6168091 | AE12: =SUM(X66:X74) -> 702 | AK12: =W50 -> Balloon Boy | AM12: =AD66 -> 0 | AO12: =AH17 -> 2 | AP12: =SUM(AL12:AO12) -> 2
A13: admin2, amc | D13: 0 | H13: 0 | L13: 0 | P13: 0 | S13: 0 | W13: Araya, Kidane | X13: =VLOOKUP(W13,$A$12:$S$57, 4,FALSE) -> 325 | Y13: =VLOOKUP(W13,$A$12:$S$57, 8,FALSE) -> 865 | Z13: =VLOOKUP(W13,$A$12:$S$57, 16,FALSE) -> 2.66 | AC13: THEATRE | AD13: =I9 -> 2.68 | AE13: =SUM(D12:D55) -> 4011 | AG13: Earned Points Ranking | AK13: =W63 -> Foxy | AM13: =AD78 -> 2 | AO13: =AH18 -> 0 | AP13: =SUM(AL13:AO13) -> 2
A14: Administrator, RSM | D14: 0 | H14: 0 | L14: 0 | P14: 0 | S14: 0 | W14: Gemmer, Jake | X14: =VLOOKUP(W14,$A$12:$S$57, 4,FALSE) -> 61 | Y14: =VLOOKUP(W14,$A$12:$S$57, 8,FALSE) -> 163 | Z14: =VLOOKUP(W14,$A$12:$S$57, 16,FALSE) -> 2.67 | AG14: =W8 -> Chica | AH14: =IF(AG14=$AH$8,3,IF(AG14=$AH$9,2,IF(AG14=$AH$10,1,0))) -> 1
A15: Albert, Rowan | D15: 235 | H15: 676 | L15: 6740.44 | P15: 2.88 | S15: 28.68 | W15: Jackson, Parker | X15: =VLOOKUP(W15,$A$12:$S$57, 4,FALSE) -> 49 | Y15: =VLOOKUP(W15,$A$12:$S$57, 8,FALSE) -> 117 | Z15: =VLOOKUP(W15,$A$12:$S$57, 16,FALSE) -> 2.39 | AG15: =W22 -> Bonnie | AH15: =IF(AG15=$AH$8,3,IF(AG15=$AH$9,2,IF(AG15=$AH$10,1,0))) -> 0 | AM15: Leaderboard
A16: Alemayehu, Eyouel | D16: 145 | H16: 334 | L16: 3250.72 | P16: 2.3 | S16: 22.42 | W16: Mccarty, Katelynn | X16: =VLOOKUP(W16,$A$12:$S$57, 4,FALSE) -> 212 | Y16: =VLOOKUP(W16,$A$12:$S$57, 8,FALSE) -> 589 | Z16: =VLOOKUP(W16,$A$12:$S$57, 16,FALSE) -> 2.78 | AG16: =W36 -> Freddy | AH16: =IF(AG16=$AH$8,3,IF(AG16=$AH$9,2,IF(AG16=$AH$10,1,0))) -> 3 | AM16: First | AN16: =INDEX($AK$9:$AK$13, MATCH(LARGE($AP$9:$AP$13, 1), $AP$9:$AP$13, 0)) -> Freddy
A17: Allen, Wren | D17: 261 | H17: 697 | L17: 6541.47 | P17: 2.67 | S17: 25.06 | W17: Montero, Rowan | X17: =VLOOKUP(W17,$A$12:$S$57, 4,FALSE) -> 199 | Y17: =VLOOKUP(W17,$A$12:$S$57, 8,FALSE) -> 506 | Z17: =VLOOKUP(W17,$A$12:$S$57, 16,FALSE) -> 2.54 | AC17: =W8 -> Chica | AD17: Bonus Points? | AG17: =W50 -> Balloon Boy | AH17: =IF(AG17=$AH$8,3,IF(AG17=$AH$9,2,IF(AG17=$AH$10,1,0))) -> 2 | AM17: Second | AN17: =INDEX($AK$9:$AK$13, MATCH(LARGE($AP$9:$AP$13, 2), $AP$9:$AP$13, 0)) -> Chica
A18: Araya, Kidane | D18: 325 | H18: 865 | L18: 8198.97 | P18: 2.66 | S18: 25.23 | W18: Pepper, Court | X18: =VLOOKUP(W18,$A$12:$S$57, 4,FALSE) -> 83 | Y18: =VLOOKUP(W18,$A$12:$S$57, 8,FALSE) -> 235 | Z18: =VLOOKUP(W18,$A$12:$S$57, 16,FALSE) -> 2.83 | AC18: =W11 -> Lopez, Ebony | AD18: =IF(VLOOKUP(AC18,$W:$Z,2,FALSE)>=100, IF(VLOOKUP(AC18,$W:$Z,4,FALSE)>$AD$13, IF(VLOOKUP(AC18,$W:$Z,4,FALSE)>=$AD$13+0.5,3, IF(VLOOKUP(AC18,$W:$Z,4,FALSE)>=$AD$13+0.25,2,1) ), 0), 0) -> 0 | AG18: =W63 -> Foxy | AH18: =IF(AG18=$AH$8,3,IF(AG18=$AH$9,2,IF(AG18=$AH$10,1,0))) -> 0 | AM18: Third | AN18: =INDEX($AK$9:$AK$13, MATCH(LARGE($AP$9:$AP$13, 3), $AP$9:$AP$13, 0)) -> Chica
A19: Clemensen, Belle | D19: 93 | H19: 283 | L19: 2694.83 | P19: 3.04 | S19: 28.98 | W19: Taylor, Ronni | X19: =VLOOKUP(W19,$A$12:$S$57, 4,FALSE) -> 136 | Y19: =VLOOKUP(W19,$A$12:$S$57, 8,FALSE) -> 357 | Z19: =VLOOKUP(W19,$A$12:$S$57, 16,FALSE) -> 2.63 | AC19: =W12 -> Allen, Wren | AD19: =IF(VLOOKUP(AC19,$W:$Z,2,FALSE)>=100, IF(VLOOKUP(AC19,$W:$Z,4,FALSE)>$AD$13, IF(VLOOKUP(AC19,$W:$Z,4,FALSE)>=$AD$13+0.5,3, IF(VLOOKUP(AC19,$W:$Z,4,FALSE)>=$AD$13+0.25,2,1) ), 0), 0) -> 0 | AM19: Fourth | AN19: =INDEX($AK$9:$AK$13, MATCH(LARGE($AP$9:$AP$13, 4), $AP$9:$AP$13, 0)) -> Chica
A20: Cloud, Annette | D20: 0 | H20: 0 | L20: 0 | P20: 0 | S20: 0 | W20: Admin, AMC | X20: =VLOOKUP(W20,$A$12:$S$57, 4,FALSE) -> 0 | Y20: =VLOOKUP(W20,$A$12:$S$57, 8,FALSE) -> 0 | Z20: =VLOOKUP(W20,$A$12:$S$57, 16,FALSE) -> 0 | AC20: =W13 -> Araya, Kidane | AD20: =IF(VLOOKUP(AC20,$W:$Z,2,FALSE)>=100, IF(VLOOKUP(AC20,$W:$Z,4,FALSE)>$AD$13, IF(VLOOKUP(AC20,$W:$Z,4,FALSE)>=$AD$13+0.5,3, IF(VLOOKUP(AC20,$W:$Z,4,FALSE)>=$AD$13+0.25,2,1) ), 0), 0) -> 0 | AM20: Fifth | AN20: =INDEX($AK$9:$AK$13, MATCH(LARGE($AP$9:$AP$13, 5), $AP$9:$AP$13, 0)) -> Bonnie
A21: DaPra, Kylan | D21: 51 | H21: 138 | L21: 1285.71 | P21: 2.71 | S21: 25.21 | AC21: =W14 -> Gemmer, Jake | AD21: =IF(VLOOKUP(AC21,$W:$Z,2,FALSE)>=100, IF(VLOOKUP(AC21,$W:$Z,4,FALSE)>$AD$13, IF(VLOOKUP(AC21,$W:$Z,4,FALSE)>=$AD$13+0.5,3, IF(VLOOKUP(AC21,$W:$Z,4,FALSE)>=$AD$13+0.25,2,1) ), 0), 0) -> 0
A22: Delelu, Samra | D22: 0 | H22: 0 | L22: 0 | P22: 0 | S22: 0 | W22: Bonnie | Y22: UPT | Z22: =(SUM(Y25:Y34)/SUM(X25:X34)) -> 2.5670498 | AC22: =W15 -> Jackson, Parker | AD22: =IF(VLOOKUP(AC22,$W:$Z,2,FALSE)>=100, IF(VLOOKUP(AC22,$W:$Z,4,FALSE)>$AD$13, IF(VLOOKUP(AC22,$W:$Z,4,FALSE)>=$AD$13+0.5,3, IF(VLOOKUP(AC22,$W:$Z,4,FALSE)>=$AD$13+0.25,2,1) ), 0), 0) -> 0
A23: Dick, Emilie | D23: 89 | H23: 234 | L23: 2188.61 | P23: 2.63 | S23: 24.59 | AC23: =W16 -> Mccarty, Katelynn | AD23: =IF(VLOOKUP(AC23,$W:$Z,2,FALSE)>=100, IF(VLOOKUP(AC23,$W:$Z,4,FALSE)>$AD$13, IF(VLOOKUP(AC23,$W:$Z,4,FALSE)>=$AD$13+0.5,3, IF(VLOOKUP(AC23,$W:$Z,4,FALSE)>=$AD$13+0.25,2,1) ), 0), 0) -> 1
A24: Farmer, Kasey | D24: 52 | H24: 122 | L24: 1157.09 | P24: 2.35 | S24: 22.25 | X24: # Transactions | Y24: # of Units Sold | Z24: UPT | AC24: =W17 -> Montero, Rowan | AD24: =IF(VLOOKUP(AC24,$W:$Z,2,FALSE)>=100, IF(VLOOKUP(AC24,$W:$Z,4,FALSE)>$AD$13, IF(VLOOKUP(AC24,$W:$Z,4,FALSE)>=$AD$13+0.5,3, IF(VLOOKUP(AC24,$W:$Z,4,FALSE)>=$AD$13+0.25,2,1) ), 0), 0) -> 0
A25: Gashu, Amanuel | D25: 34 | H25: 87 | L25: 932.88 | P25: 2.56 | S25: 27.44 | W25: Zeller, Daniel | X25: =VLOOKUP(W25,$A$12:$S$57, 4,FALSE) -> 35 | Y25: =VLOOKUP(W25,$A$12:$S$57, 8,FALSE) -> 82 | Z25: =VLOOKUP(W25,$A$12:$S$57, 16,FALSE) -> 2.34 | AC25: =W18 -> Pepper, Court | AD25: =IF(VLOOKUP(AC25,$W:$Z,2,FALSE)>=100, IF(VLOOKUP(AC25,$W:$Z,4,FALSE)>$AD$13, IF(VLOOKUP(AC25,$W:$Z,4,FALSE)>=$AD$13+0.5,3, IF(VLOOKUP(AC25,$W:$Z,4,FALSE)>=$AD$13+0.25,2,1) ), 0), 0) -> 0
A26: Gemmer, Jake | D26: 61 | H26: 163 | L26: 1577.16 | P26: 2.67 | S26: 25.86 | W26: Dick, Emilie | X26: =VLOOKUP(W26,$A$12:$S$57, 4,FALSE) -> 89 | Y26: =VLOOKUP(W26,$A$12:$S$57, 8,FALSE) -> 234 | Z26: =VLOOKUP(W26,$A$12:$S$57, 16,FALSE) -> 2.63 | AC26: =W19 -> Taylor, Ronni | AD26: =IF(VLOOKUP(AC26,$W:$Z,2,FALSE)>=100, IF(VLOOKUP(AC26,$W:$Z,4,FALSE)>$AD$13, IF(VLOOKUP(AC26,$W:$Z,4,FALSE)>=$AD$13+0.5,3, IF(VLOOKUP(AC26,$W:$Z,4,FALSE)>=$AD$13+0.25,2,1) ), 0), 0) -> 0
A27: Grover, Grover | D27: 0 | H27: 0 | L27: 0 | P27: 0 | S27: 0 | W27: Farmer, Kasey | X27: =VLOOKUP(W27,$A$12:$S$57, 4,FALSE) -> 52 | Y27: =VLOOKUP(W27,$A$12:$S$57, 8,FALSE) -> 122 | Z27: =VLOOKUP(W27,$A$12:$S$57, 16,FALSE) -> 2.35 | AC27: =W20 -> Admin, AMC | AD27: =IF(VLOOKUP(AC27,$W:$Z,2,FALSE)>=100, IF(VLOOKUP(AC27,$W:$Z,4,FALSE)>$AD$13, IF(VLOOKUP(AC27,$W:$Z,4,FALSE)>=$AD$13+0.5,3, IF(VLOOKUP(AC27,$W:$Z,4,FALSE)>=$AD$13+0.25,2,1) ), 0), 0) -> 0
A28: Hatch, Aidan | D28: 81 | H28: 214 | L28: 1973.27 | P28: 2.64 | S28: 24.36 | W28: Gashu, Amanuel | X28: =VLOOKUP(W28,$A$12:$S$57, 4,FALSE) -> 34 | Y28: =VLOOKUP(W28,$A$12:$S$57, 8,FALSE) -> 87 | Z28: =VLOOKUP(W28,$A$12:$S$57, 16,FALSE) -> 2.56 | AC28: Total Bonus | AD28: =SUM(AD18:AD27) -> 1
A29: Hill, Gabby | D29: 105 | H29: 298 | L29: 2752.74 | P29: 2.84 | S29: 26.22 | W29: Grover, Grover | X29: =VLOOKUP(W29,$A$12:$S$57, 4,FALSE) -> 0 | Y29: =VLOOKUP(W29,$A$12:$S$57, 8,FALSE) -> 0 | Z29: =VLOOKUP(W29,$A$12:$S$57, 16,FALSE) -> 0
A30: Isreal, Zeal | D30: 73 | H30: 199 | L30: 1721.93 | P30: 2.73 | S30: 23.59 | W30: Hatch, Aidan | X30: =VLOOKUP(W30,$A$12:$S$57, 4,FALSE) -> 81 | Y30: =VLOOKUP(W30,$A$12:$S$57, 8,FALSE) -> 214 | Z30: =VLOOKUP(W30,$A$12:$S$57, 16,FALSE) -> 2.64 | AC30: =W22 -> Bonnie | AD30: Bonus Points?
A31: Jackson, Parker | D31: 49 | H31: 117 | L31: 1131.97 | P31: 2.39 | S31: 23.1 | W31: Miller, Taytem | X31: =VLOOKUP(W31,$A$12:$S$57, 4,FALSE) -> 67 | Y31: =VLOOKUP(W31,$A$12:$S$57, 8,FALSE) -> 174 | Z31: =VLOOKUP(W31,$A$12:$S$57, 16,FALSE) -> 2.6 | AC31: =W25 -> Zeller, Daniel | AD31: =IF(VLOOKUP(AC31,$W:$Z,2,FALSE)>=100, IF(VLOOKUP(AC31,$W:$Z,4,FALSE)>$AD$13, IF(VLOOKUP(AC31,$W:$Z,4,FALSE)>=$AD$13+0.5,3, IF(VLOOKUP(AC31,$W:$Z,4,FALSE)>=$AD$13+0.25,2,1) ), 0), 0) -> 0
A32: Kelly, Ryan | D32: 25 | H32: 197 | L32: 1878.42 | P32: 7.88 | S32: 75.14 | W32: Ryder, Erin | X32: =VLOOKUP(W32,$A$12:$S$57, 4,FALSE) -> 82 | Y32: =VLOOKUP(W32,$A$12:$S$57, 8,FALSE) -> 198 | Z32: =VLOOKUP(W32,$A$12:$S$57, 16,FALSE) -> 2.41 | AC32: =W26 -> Dick, Emilie | AD32: =IF(VLOOKUP(AC32,$W:$Z,2,FALSE)>=100, IF(VLOOKUP(AC32,$W:$Z,4,FALSE)>$AD$13, IF(VLOOKUP(AC32,$W:$Z,4,FALSE)>=$AD$13+0.5,3, IF(VLOOKUP(AC32,$W:$Z,4,FALSE)>=$AD$13+0.25,2,1) ), 0), 0) -> 0
A33: Koessler, Bayley | D33: 90 | H33: 241 | L33: 2292.42 | P33: 2.68 | S33: 25.47 | W33: Yandle, Chuck | X33: =VLOOKUP(W33,$A$12:$S$57, 4,FALSE) -> 82 | Y33: =VLOOKUP(W33,$A$12:$S$57, 8,FALSE) -> 229 | Z33: =VLOOKUP(W33,$A$12:$S$57, 16,FALSE) -> 2.79 | AC33: =W27 -> Farmer, Kasey | AD33: =IF(VLOOKUP(AC33,$W:$Z,2,FALSE)>=100, IF(VLOOKUP(AC33,$W:$Z,4,FALSE)>$AD$13, IF(VLOOKUP(AC33,$W:$Z,4,FALSE)>=$AD$13+0.5,3, IF(VLOOKUP(AC33,$W:$Z,4,FALSE)>=$AD$13+0.25,2,1) ), 0), 0) -> 0
A34: Krause, Daniel | D34: 196 | H34: 533 | L34: 5040.03 | P34: 2.72 | S34: 25.71 | W34: Admin, AMC | X34: =VLOOKUP(W34,$A$12:$S$57, 4,FALSE) -> 0 | Y34: =VLOOKUP(W34,$A$12:$S$57, 8,FALSE) -> 0 | Z34: =VLOOKUP(W34,$A$12:$S$57, 16,FALSE) -> 0 | AC34: =W28 -> Gashu, Amanuel | AD34: =IF(VLOOKUP(AC34,$W:$Z,2,FALSE)>=100, IF(VLOOKUP(AC34,$W:$Z,4,FALSE)>$AD$13, IF(VLOOKUP(AC34,$W:$Z,4,FALSE)>=$AD$13+0.5,3, IF(VLOOKUP(AC34,$W:$Z,4,FALSE)>=$AD$13+0.25,2,1) ), 0), 0) -> 0
A35: Lingg, Beckett | D35: 0 | H35: 0 | L35: 0 | P35: 0 | S35: 0 | AC35: =W29 -> Grover, Grover | AD35: =IF(VLOOKUP(AC35,$W:$Z,2,FALSE)>=100, IF(VLOOKUP(AC35,$W:$Z,4,FALSE)>$AD$13, IF(VLOOKUP(AC35,$W:$Z,4,FALSE)>=$AD$13+0.5,3, IF(VLOOKUP(AC35,$W:$Z,4,FALSE)>=$AD$13+0.25,2,1) ), 0), 0) -> 0
A36: Lopez, Ebony | D36: 85 | H36: 236 | L36: 2164.93 | P36: 2.78 | S36: 25.47 | W36: Freddy | Y36: UPT | Z36: =(SUM(Y39:Y48)/SUM(X39:X48)) -> 2.8501742 | AC36: =W30 -> Hatch, Aidan | AD36: =IF(VLOOKUP(AC36,$W:$Z,2,FALSE)>=100, IF(VLOOKUP(AC36,$W:$Z,4,FALSE)>$AD$13, IF(VLOOKUP(AC36,$W:$Z,4,FALSE)>=$AD$13+0.5,3, IF(VLOOKUP(AC36,$W:$Z,4,FALSE)>=$AD$13+0.25,2,1) ), 0), 0) -> 0
A37: Lopez, Matthew | D37: 12 | H37: 41 | L37: 352.4 | P37: 3.42 | S37: 29.37 | AC37: =W31 -> Miller, Taytem | AD37: =IF(VLOOKUP(AC37,$W:$Z,2,FALSE)>=100, IF(VLOOKUP(AC37,$W:$Z,4,FALSE)>$AD$13, IF(VLOOKUP(AC37,$W:$Z,4,FALSE)>=$AD$13+0.5,3, IF(VLOOKUP(AC37,$W:$Z,4,FALSE)>=$AD$13+0.25,2,1) ), 0), 0) -> 0
A38: Mccarty, Katelynn | D38: 212 | H38: 589 | L38: 5535.71 | P38: 2.78 | S38: 26.11 | X38: # Transactions | Y38: # of Units Sold | Z38: UPT | AC38: =W32 -> Ryder, Erin | AD38: =IF(VLOOKUP(AC38,$W:$Z,2,FALSE)>=100, IF(VLOOKUP(AC38,$W:$Z,4,FALSE)>$AD$13, IF(VLOOKUP(AC38,$W:$Z,4,FALSE)>=$AD$13+0.5,3, IF(VLOOKUP(AC38,$W:$Z,4,FALSE)>=$AD$13+0.25,2,1) ), 0), 0) -> 0
A39: McChesney, Jack | D39: 164 | H39: 418 | L39: 3763.76 | P39: 2.55 | S39: 22.95 | W39: DaPra, Kylan | X39: =VLOOKUP(W39,$A$12:$S$57, 4,FALSE) -> 51 | Y39: =VLOOKUP(W39,$A$12:$S$57, 8,FALSE) -> 138 | Z39: =VLOOKUP(W39,$A$12:$S$57, 16,FALSE) -> 2.71 | AC39: =W33 -> Yandle, Chuck | AD39: =IF(VLOOKUP(AC39,$W:$Z,2,FALSE)>=100, IF(VLOOKUP(AC39,$W:$Z,4,FALSE)>$AD$13, IF(VLOOKUP(AC39,$W:$Z,4,FALSE)>=$AD$13+0.5,3, IF(VLOOKUP(AC39,$W:$Z,4,FALSE)>=$AD$13+0.25,2,1) ), 0), 0) -> 0
A40: Miller, Taytem | D40: 67 | H40: 174 | L40: 1689.84 | P40: 2.6 | S40: 25.22 | W40: Albert, Rowan | X40: =VLOOKUP(W40,$A$12:$S$57, 4,FALSE) -> 235 | Y40: =VLOOKUP(W40,$A$12:$S$57, 8,FALSE) -> 676 | Z40: =VLOOKUP(W40,$A$12:$S$57, 16,FALSE) -> 2.88 | AC40: =W34 -> Admin, AMC | AD40: =IF(VLOOKUP(AC40,$W:$Z,2,FALSE)>=100, IF(VLOOKUP(AC40,$W:$Z,4,FALSE)>$AD$13, IF(VLOOKUP(AC40,$W:$Z,4,FALSE)>=$AD$13+0.5,3, IF(VLOOKUP(AC40,$W:$Z,4,FALSE)>=$AD$13+0.25,2,1) ), 0), 0) -> 0
...

Sheet Week 2
A1: AMC | F1: Employee AweS.U.M. Report
A2: Woodinville Unit2449 (02449)
A3: 17640 138th Pl. NE
A4: Woodinville, Washington | F4: Business Date Range: 11/28/2025 to 12/4/2025
A5: 98072- | F5: Sort By Employee
A6: UNITED STATES
M7: Average | AC7: Team | AD7: UPT | AE7: n | AG7: Winner For the Week | AK7: Scoreboard
I8: UPT | M8: Transaction | W8: Chica | Y8: Average Tranaction | Z8: =(SUM(Y11:Y20)/SUM(X11:X20)) -> 2.7761468 | AC8: =W8 -> Chica | AD8: =Z8 -> 2.7761468 | AE8: =SUM(X11:X20) -> 1090 | AG8: 1st | AH8: =INDEX($AC$8:$AC$12, MATCH(LARGE($AD$8:$AD$12, 1), $AD$8:$AD$12, 0)) -> Chica | AL8: Previous Week | AM8: Bonus Points (Individual) | AN8: Bonus Point Team Improvement | AO8: Earned Points | AP8: Total Points
G9: Theatre Average: | I9: 2.71 | O9: 25.65 | AC9: =W22 -> Bonnie | AD9: =Z22 -> 2.7297297 | AE9: =SUM(X25:X34) -> 481 | AG9: 2nd | AH9: =INDEX($AC$8:$AC$12, MATCH(LARGE($AD$8:$AD$12, 2), $AD$8:$AD$12, 0)) -> Bonnie | AK9: =W8 -> Chica | AL9: ='Week 1'!AP9 -> 2 | AM9: =AD28 -> 5 | AN9: =AH31 -> 1 | AO9: =AH14 -> 3 | AP9: =SUM(AL9:AO9) -> 11
D10: # of Transactions | X10: # Transactions | Y10: # of Units Sold | Z10: UPT | AC10: =W36 -> Freddy | AD10: =Z36 -> 2.6085919 | AE10: =SUM(X39:X48) -> 419 | AG10: 3rd | AH10: =INDEX($AC$8:$AC$12, MATCH(LARGE($AD$8:$AD$12, 3), $AD$8:$AD$12, 0)) -> Balloon Boy | AK10: =W22 -> Bonnie | AL10: ='Week 1'!AP10 -> 0 | AM10: =AD41 -> 1 | AN10: =AH32 -> 1 | AO10: =AH15 -> 2 | AP10: =SUM(AL10:AO10) -> 4
A11: Employee Name | G11: # of Units Sold | K11: Total Sales | P11: UPT | S11: Average Transaction | W11: Lopez, Ebony | X11: =VLOOKUP(W11,$A$12:$S$57, 4,FALSE) -> 180 | Y11: =VLOOKUP(W11,$A$12:$S$57, 8,FALSE) -> 510 | Z11: =VLOOKUP(W11,$A$12:$S$57, 16,FALSE) -> 2.83 | AC11: =W50 -> Balloon Boy | AD11: =Z50 -> 2.7127937 | AE11: =SUM(X53:X61) -> 766 | AK11: =W36 -> Freddy | AL11: ='Week 1'!AP11 -> 5 | AM11: =AD54 -> 0 | AN11: =AH33 -> 0 | AO11: =AH16 -> 0 | AP11: =SUM(AL11:AO11) -> 5
A12: Admin, AMC | D12: 0 | H12: 0 | L12: 0 | P12: 0 | S12: 0 | W12: Allen, Wren | X12: =VLOOKUP(W12,$A$12:$S$57, 4,FALSE) -> 170 | Y12: =VLOOKUP(W12,$A$12:$S$57, 8,FALSE) -> 503 | Z12: =VLOOKUP(W12,$A$12:$S$57, 16,FALSE) -> 2.96 | AC12: =W63 -> Foxy | AD12: =Z63 -> 2.602 | AE12: =SUM(X66:X74) -> 500 | AK12: =W50 -> Balloon Boy | AL12: ='Week 1'!AP12 -> 2 | AM12: =AD66 -> 3 | AN12: =AH34 -> 1 | AO12: =AH17 -> 1 | AP12: =SUM(AL12:AO12) -> 7
A13: admin2, amc | D13: 0 | H13: 0 | L13: 0 | P13: 0 | S13: 0 | W13: Araya, Kidane | X13: =VLOOKUP(W13,$A$12:$S$57, 4,FALSE) -> 133 | Y13: =VLOOKUP(W13,$A$12:$S$57, 8,FALSE) -> 314 | Z13: =VLOOKUP(W13,$A$12:$S$57, 16,FALSE) -> 2.36 | AC13: THEATRE | AD13: =I9 -> 2.71 | AE13: =SUM(D12:D55) -> 3256 | AG13: Earned Points Ranking | AK13: =W63 -> Foxy | AL13: ='Week 1'!AP13 -> 2 | AM13: =AD78 -> 0 | AN13: =AH35 -> 0 | AO13: =AH18 -> 0 | AP13: =SUM(AL13:AO13) -> 2
A14: Administrator, RSM | D14: 0 | H14: 0 | L14: 0 | P14: 0 | S14: 0 | W14: Gemmer, Jake | X14: =VLOOKUP(W14,$A$12:$S$57, 4,FALSE) -> 99 | Y14: =VLOOKUP(W14,$A$12:$S$57, 8,FALSE) -> 272 | Z14: =VLOOKUP(W14,$A$12:$S$57, 16,FALSE) -> 2.75 | AG14: =W8 -> Chica | AH14: =IF(AG14=$AH$8,3,IF(AG14=$AH$9,2,IF(AG14=$AH$10,1,0))) -> 3
A15: Albert, Rowan | D15: 178 | H15: 470 | L15: 4311.18 | P15: 2.64 | S15: 24.22 | W15: Jackson, Parker | X15: =VLOOKUP(W15,$A$12:$S$57, 4,FALSE) -> 112 | Y15: =VLOOKUP(W15,$A$12:$S$57, 8,FALSE) -> 330 | Z15: =VLOOKUP(W15,$A$12:$S$57, 16,FALSE) -> 2.95 | AG15: =W22 -> Bonnie | AH15: =IF(AG15=$AH$8,3,IF(AG15=$AH$9,2,IF(AG15=$AH$10,1,0))) -> 2 | AM15: Leaderboard
A16: Alemayehu, Eyouel | D16: 0 | H16: 0 | L16: 0 | P16: 0 | S16: 0 | W16: Mccarty, Katelynn | X16: =VLOOKUP(W16,$A$12:$S$57, 4,FALSE) -> 61 | Y16: =VLOOKUP(W16,$A$12:$S$57, 8,FALSE) -> 151 | Z16: =VLOOKUP(W16,$A$12:$S$57, 16,FALSE) -> 2.48 | AG16: =W36 -> Freddy | AH16: =IF(AG16=$AH$8,3,IF(AG16=$AH$9,2,IF(AG16=$AH$10,1,0))) -> 0 | AM16: First | AN16: =INDEX($AK$9:$AK$13, MATCH(LARGE($AP$9:$AP$13, 1), $AP$9:$AP$13, 0)) -> Chica
A17: Allen, Wren | D17: 170 | H17: 503 | L17: 4755.16 | P17: 2.96 | S17: 27.97 | W17: Montero, Rowan | X17: =VLOOKUP(W17,$A$12:$S$57, 4,FALSE) -> 101 | Y17: =VLOOKUP(W17,$A$12:$S$57, 8,FALSE) -> 244 | Z17: =VLOOKUP(W17,$A$12:$S$57, 16,FALSE) -> 2.42 | AC17: =W8 -> Chica | AD17: Bonus Points? | AG17: =W50 -> Balloon Boy | AH17: =IF(AG17=$AH$8,3,IF(AG17=$AH$9,2,IF(AG17=$AH$10,1,0))) -> 1 | AM17: Second | AN17: =INDEX($AK$9:$AK$13, MATCH(LARGE($AP$9:$AP$13, 2), $AP$9:$AP$13, 0)) -> Balloon Boy
A18: Araya, Kidane | D18: 133 | H18: 314 | L18: 2830.17 | P18: 2.36 | S18: 21.28 | W18: Pepper, Court | X18: =VLOOKUP(W18,$A$12:$S$57, 4,FALSE) -> 143 | Y18: =VLOOKUP(W18,$A$12:$S$57, 8,FALSE) -> 420 | Z18: =VLOOKUP(W18,$A$12:$S$57, 16,FALSE) -> 2.94 | AC18: =W11 -> Lopez, Ebony | AD18: =IF(VLOOKUP(AC18,$W:$Z,2,FALSE)>=100, IF(VLOOKUP(AC18,$W:$Z,4,FALSE)>$AD$13, IF(VLOOKUP(AC18,$W:$Z,4,FALSE)>=$AD$13+0.5,3, IF(VLOOKUP(AC18,$W:$Z,4,FALSE)>=$AD$13+0.25,2,1) ), 0), 0) -> 1 | AG18: =W63 -> Foxy | AH18: =IF(AG18=$AH$8,3,IF(AG18=$AH$9,2,IF(AG18=$AH$10,1,0))) -> 0 | AM18: Third | AN18: =INDEX($AK$9:$AK$13, MATCH(LARGE($AP$9:$AP$13, 3), $AP$9:$AP$13, 0)) -> Freddy
A19: Clemensen, Belle | D19: 172 | H19: 428 | L19: 3920.75 | P19: 2.49 | S19: 22.8 | W19: Taylor, Ronni | X19: =VLOOKUP(W19,$A$12:$S$57, 4,FALSE) -> 91 | Y19: =VLOOKUP(W19,$A$12:$S$57, 8,FALSE) -> 282 | Z19: =VLOOKUP(W19,$A$12:$S$57, 16,FALSE) -> 3.1 | AC19: =W12 -> Allen, Wren | AD19: =IF(VLOOKUP(AC19,$W:$Z,2,FALSE)>=100, IF(VLOOKUP(AC19,$W:$Z,4,FALSE)>$AD$13, IF(VLOOKUP(AC19,$W:$Z,4,FALSE)>=$AD$13+0.5,3, IF(VLOOKUP(AC19,$W:$Z,4,FALSE)>=$AD$13+0.25,2,1) ), 0), 0) -> 2 | AM19: Fourth | AN19: =INDEX($AK$9:$AK$13, MATCH(LARGE($AP$9:$AP$13, 4), $AP$9:$AP$13, 0)) -> Bonnie
A20: Cloud, Annette | D20: 0 | H20: 0 | L20: 0 | P20: 0 | S20: 0 | V20: keira | W20: Admin, AMC | X20: =VLOOKUP(W20,$A$12:$S$57, 4,FALSE) -> 0 | Y20: =VLOOKUP(W20,$A$12:$S$57, 8,FALSE) -> 0 | Z20: =VLOOKUP(W20,$A$12:$S$57, 16,FALSE) -> 0 | AC20: =W13 -> Araya, Kidane | AD20: =IF(VLOOKUP(AC20,$W:$Z,2,FALSE)>=100, IF(VLOOKUP(AC20,$W:$Z,4,FALSE)>$AD$13, IF(VLOOKUP(AC20,$W:$Z,4,FALSE)>=$AD$13+0.5,3, IF(VLOOKUP(AC20,$W:$Z,4,FALSE)>=$AD$13+0.25,2,1) ), 0), 0) -> 0 | AM20: Fifth | AN20: =INDEX($AK$9:$AK$13, MATCH(LARGE($AP$9:$AP$13, 5), $AP$9:$AP$13, 0)) -> Foxy
A21: DaPra, Kylan | D21: 57 | H21: 158 | L21: 1539.07 | P21: 2.77 | S21: 27 | AC21: =W14 -> Gemmer, Jake | AD21: =IF(VLOOKUP(AC21,$W:$Z,2,FALSE)>=100, IF(VLOOKUP(AC21,$W:$Z,4,FALSE)>$AD$13, IF(VLOOKUP(AC21,$W:$Z,4,FALSE)>=$AD$13+0.5,3, IF(VLOOKUP(AC21,$W:$Z,4,FALSE)>=$AD$13+0.25,2,1) ), 0), 0) -> 0 | AG21: Last Week
A22: Delelu, Samra | D22: 0 | H22: 0 | L22: 0 | P22: 0 | S22: 0 | W22: Bonnie | Y22: UPT | Z22: =(SUM(Y25:Y34)/SUM(X25:X34)) -> 2.7297297 | AC22: =W15 -> Jackson, Parker | AD22: =IF(VLOOKUP(AC22,$W:$Z,2,FALSE)>=100, IF(VLOOKUP(AC22,$W:$Z,4,FALSE)>$AD$13, IF(VLOOKUP(AC22,$W:$Z,4,FALSE)>=$AD$13+0.5,3, IF(VLOOKUP(AC22,$W:$Z,4,FALSE)>=$AD$13+0.25,2,1) ), 0), 0) -> 1 | AG22: Team | AH22: UPT
A23: Dick, Emilie | D23: 52 | H23: 133 | L23: 1210.2 | P23: 2.56 | S23: 23.27 | AC23: =W16 -> Mccarty, Katelynn | AD23: =IF(VLOOKUP(AC23,$W:$Z,2,FALSE)>=100, IF(VLOOKUP(AC23,$W:$Z,4,FALSE)>$AD$13, IF(VLOOKUP(AC23,$W:$Z,4,FALSE)>=$AD$13+0.5,3, IF(VLOOKUP(AC23,$W:$Z,4,FALSE)>=$AD$13+0.25,2,1) ), 0), 0) -> 0 | AG23: =W8 -> Chica | AH23: ='Week 1'!AD8 -> 2.6683203
A24: Farmer, Kasey | D24: 105 | H24: 256 | L24: 2381.08 | P24: 2.44 | S24: 22.68 | X24: # Transactions | Y24: # of Units Sold | Z24: UPT | AC24: =W17 -> Montero, Rowan | AD24: =IF(VLOOKUP(AC24,$W:$Z,2,FALSE)>=100, IF(VLOOKUP(AC24,$W:$Z,4,FALSE)>$AD$13, IF(VLOOKUP(AC24,$W:$Z,4,FALSE)>=$AD$13+0.5,3, IF(VLOOKUP(AC24,$W:$Z,4,FALSE)>=$AD$13+0.25,2,1) ), 0), 0) -> 0 | AG24: =W22 -> Bonnie | AH24: ='Week 1'!AD9 -> 2.5670498
A25: Gashu, Amanuel | D25: 60 | H25: 188 | L25: 1731.31 | P25: 3.13 | S25: 28.86 | W25: Zeller, Daniel | X25: =VLOOKUP(W25,$A$12:$S$57, 4,FALSE) -> 25 | Y25: =VLOOKUP(W25,$A$12:$S$57, 8,FALSE) -> 75 | Z25: =VLOOKUP(W25,$A$12:$S$57, 16,FALSE) -> 3 | AC25: =W18 -> Pepper, Court | AD25: =IF(VLOOKUP(AC25,$W:$Z,2,FALSE)>=100, IF(VLOOKUP(AC25,$W:$Z,4,FALSE)>$AD$13, IF(VLOOKUP(AC25,$W:$Z,4,FALSE)>=$AD$13+0.5,3, IF(VLOOKUP(AC25,$W:$Z,4,FALSE)>=$AD$13+0.25,2,1) ), 0), 0) -> 1 | AG25: =W36 -> Freddy | AH25: ='Week 1'!AD10 -> 2.8501742
A26: Gemmer, Jake | D26: 99 | H26: 272 | L26: 2468.5 | P26: 2.75 | S26: 24.93 | W26: Dick, Emilie | X26: =VLOOKUP(W26,$A$12:$S$57, 4,FALSE) -> 52 | Y26: =VLOOKUP(W26,$A$12:$S$57, 8,FALSE) -> 133 | Z26: =VLOOKUP(W26,$A$12:$S$57, 16,FALSE) -> 2.56 | AC26: =W19 -> Taylor, Ronni | AD26: =IF(VLOOKUP(AC26,$W:$Z,2,FALSE)>=100, IF(VLOOKUP(AC26,$W:$Z,4,FALSE)>$AD$13, IF(VLOOKUP(AC26,$W:$Z,4,FALSE)>=$AD$13+0.5,3, IF(VLOOKUP(AC26,$W:$Z,4,FALSE)>=$AD$13+0.25,2,1) ), 0), 0) -> 0 | AG26: =W50 -> Balloon Boy | AH26: ='Week 1'!AD11 -> 2.6995012
A27: Grover, Grover | D27: 0 | H27: 0 | L27: 0 | P27: 0 | S27: 0 | W27: Farmer, Kasey | X27: =VLOOKUP(W27,$A$12:$S$57, 4,FALSE) -> 105 | Y27: =VLOOKUP(W27,$A$12:$S$57, 8,FALSE) -> 256 | Z27: =VLOOKUP(W27,$A$12:$S$57, 16,FALSE) -> 2.44 | AC27: =W20 -> Admin, AMC | AD27: =IF(VLOOKUP(AC27,$W:$Z,2,FALSE)>=100, IF(VLOOKUP(AC27,$W:$Z,4,FALSE)>$AD$13, IF(VLOOKUP(AC27,$W:$Z,4,FALSE)>=$AD$13+0.5,3, IF(VLOOKUP(AC27,$W:$Z,4,FALSE)>=$AD$13+0.25,2,1) ), 0), 0) -> 0 | AG27: =W63 -> Foxy | AH27: ='Week 1'!AD12 -> 2.6168091
A28: Hatch, Aidan | D28: 0 | H28: 0 | L28: 0 | P28: 0 | S28: 0 | W28: Gashu, Amanuel | X28: =VLOOKUP(W28,$A$12:$S$57, 4,FALSE) -> 60 | Y28: =VLOOKUP(W28,$A$12:$S$57, 8,FALSE) -> 188 | Z28: =VLOOKUP(W28,$A$12:$S$57, 16,FALSE) -> 3.13 | AC28: Total Bonus | AD28: =SUM(AD18:AD27) -> 5
A29: Hill, Gabby | D29: 12 | H29: 37 | L29: 351.48 | P29: 3.08 | S29: 29.29 | W29: Grover, Grover | X29: =VLOOKUP(W29,$A$12:$S$57, 4,FALSE) -> 0 | Y29: =VLOOKUP(W29,$A$12:$S$57, 8,FALSE) -> 0 | Z29: =VLOOKUP(W29,$A$12:$S$57, 16,FALSE) -> 0
A30: Isreal, Zeal | D30: 217 | H30: 593 | L30: 5319.91 | P30: 2.73 | S30: 24.52 | W30: Hatch, Aidan | X30: =VLOOKUP(W30,$A$12:$S$57, 4,FALSE) -> 0 | Y30: =VLOOKUP(W30,$A$12:$S$57, 8,FALSE) -> 0 | Z30: =VLOOKUP(W30,$A$12:$S$57, 16,FALSE) -> 0 | AC30: =W22 -> Bonnie | AD30: Bonus Points? | AG30: Bonus Point for Team Improvement?
A31: Jackson, Parker | D31: 112 | H31: 330 | L31: 3000.93 | P31: 2.95 | S31: 26.79 | W31: Miller, Taytem | X31: =VLOOKUP(W31,$A$12:$S$57, 4,FALSE) -> 23 | Y31: =VLOOKUP(W31,$A$12:$S$57, 8,FALSE) -> 62 | Z31: =VLOOKUP(W31,$A$12:$S$57, 16,FALSE) -> 2.7 | AC31: =W25 -> Zeller, Daniel | AD31: =IF(VLOOKUP(AC31,$W:$Z,2,FALSE)>=100, IF(VLOOKUP(AC31,$W:$Z,4,FALSE)>$AD$13, IF(VLOOKUP(AC31,$W:$Z,4,FALSE)>=$AD$13+0.5,3, IF(VLOOKUP(AC31,$W:$Z,4,FALSE)>=$AD$13+0.25,2,1) ), 0), 0) -> 0 | AG31: =W8 -> Chica | AH31: =IF(AD8>AH23,1,0) -> 1
A32: Kelly, Ryan | D32: 14 | H32: 37 | L32: 315.66 | P32: 2.64 | S32: 22.55 | W32: Ryder, Erin | X32: =VLOOKUP(W32,$A$12:$S$57, 4,FALSE) -> 76 | Y32: =VLOOKUP(W32,$A$12:$S$57, 8,FALSE) -> 217 | Z32: =VLOOKUP(W32,$A$12:$S$57, 16,FALSE) -> 2.86 | AC32: =W26 -> Dick, Emilie | AD32: =IF(VLOOKUP(AC32,$W:$Z,2,FALSE)>=100, IF(VLOOKUP(AC32,$W:$Z,4,FALSE)>$AD$13, IF(VLOOKUP(AC32,$W:$Z,4,FALSE)>=$AD$13+0.5,3, IF(VLOOKUP(AC32,$W:$Z,4,FALSE)>=$AD$13+0.25,2,1) ), 0), 0) -> 0 | AG32: =W22 -> Bonnie | AH32: =IF(AD9>AH24, 1,0) -> 1
A33: Koessler, Bayley | D33: 0 | H33: 0 | L33: 0 | P33: 0 | S33: 0 | W33: Yandle, Chuck | X33: =VLOOKUP(W33,$A$12:$S$57, 4,FALSE) -> 140 | Y33: =VLOOKUP(W33,$A$12:$S$57, 8,FALSE) -> 382 | Z33: =VLOOKUP(W33,$A$12:$S$57, 16,FALSE) -> 2.73 | AC33: =W27 -> Farmer, Kasey | AD33: =IF(VLOOKUP(AC33,$W:$Z,2,FALSE)>=100, IF(VLOOKUP(AC33,$W:$Z,4,FALSE)>$AD$13, IF(VLOOKUP(AC33,$W:$Z,4,FALSE)>=$AD$13+0.5,3, IF(VLOOKUP(AC33,$W:$Z,4,FALSE)>=$AD$13+0.25,2,1) ), 0), 0) -> 0 | AG33: =W36 -> Freddy | AH33: =IF(AD10>AH25, 1,0) -> 0
A34: Krause, Daniel | D34: 191 | H34: 515 | L34: 4776.96 | P34: 2.7 | S34: 25.01 | V34: abby | W34: Admin, AMC | X34: =VLOOKUP(W34,$A$12:$S$57, 4,FALSE) -> 0 | Y34: =VLOOKUP(W34,$A$12:$S$57, 8,FALSE) -> 0 | Z34: =VLOOKUP(W34,$A$12:$S$57, 16,FALSE) -> 0 | AC34: =W28 -> Gashu, Amanuel | AD34: =IF(VLOOKUP(AC34,$W:$Z,2,FALSE)>=100, IF(VLOOKUP(AC34,$W:$Z,4,FALSE)>$AD$13, IF(VLOOKUP(AC34,$W:$Z,4,FALSE)>=$AD$13+0.5,3, IF(VLOOKUP(AC34,$W:$Z,4,FALSE)>=$AD$13+0.25,2,1) ), 0), 0) -> 0 | AG34: =W50 -> Balloon Boy | AH34: =IF(AD11>AH26, 1,0) -> 1
A35: Lingg, Beckett | D35: 0 | H35: 0 | L35: 0 | P35: 0 | S35: 0 | AC35: =W29 -> Grover, Grover | AD35: =IF(VLOOKUP(AC35,$W:$Z,2,FALSE)>=100, IF(VLOOKUP(AC35,$W:$Z,4,FALSE)>$AD$13, IF(VLOOKUP(AC35,$W:$Z,4,FALSE)>=$AD$13+0.5,3, IF(VLOOKUP(AC35,$W:$Z,4,FALSE)>=$AD$13+0.25,2,1) ), 0), 0) -> 0 | AG35: =W63 -> Foxy | AH35: =IF(AD12>AH27, 1,0) -> 0
A36: Lopez, Ebony | D36: 180 | H36: 510 | L36: 4681.6 | P36: 2.83 | S36: 26.01 | W36: Freddy | Y36: UPT | Z36: =(SUM(Y39:Y48)/SUM(X39:X48)) -> 2.6085919 | AC36: =W30 -> Hatch, Aidan | AD36: =IF(VLOOKUP(AC36,$W:$Z,2,FALSE)>=100, IF(VLOOKUP(AC36,$W:$Z,4,FALSE)>$AD$13, IF(VLOOKUP(AC36,$W:$Z,4,FALSE)>=$AD$13+0.5,3, IF(VLOOKUP(AC36,$W:$Z,4,FALSE)>=$AD$13+0.25,2,1) ), 0), 0) -> 0
A37: Lopez, Matthew | D37: 58 | H37: 192 | L37: 1720.68 | P37: 3.31 | S37: 29.67 | AC37: =W31 -> Miller, Taytem | AD37: =IF(VLOOKUP(AC37,$W:$Z,2,FALSE)>=100, IF(VLOOKUP(AC37,$W:$Z,4,FALSE)>$AD$13, IF(VLOOKUP(AC37,$W:$Z,4,FALSE)>=$AD$13+0.5,3, IF(VLOOKUP(AC37,$W:$Z,4,FALSE)>=$AD$13+0.25,2,1) ), 0), 0) -> 0
A38: Mccarty, Katelynn | D38: 61 | H38: 151 | L38: 1429.46 | P38: 2.48 | S38: 23.43 | X38: # Transactions | Y38: # of Units Sold | Z38: UPT | AC38: =W32 -> Ryder, Erin | AD38: =IF(VLOOKUP(AC38,$W:$Z,2,FALSE)>=100, IF(VLOOKUP(AC38,$W:$Z,4,FALSE)>$AD$13, IF(VLOOKUP(AC38,$W:$Z,4,FALSE)>=$AD$13+0.5,3, IF(VLOOKUP(AC38,$W:$Z,4,FALSE)>=$AD$13+0.25,2,1) ), 0), 0) -> 0
A39: McChesney, Jack | D39: 102 | H39: 229 | L39: 2006.11 | P39: 2.25 | S39: 19.67 | W39: DaPra, Kylan | X39: =VLOOKUP(W39,$A$12:$S$57, 4,FALSE) -> 57 | Y39: =VLOOKUP(W39,$A$12:$S$57, 8,FALSE) -> 158 | Z39: =VLOOKUP(W39,$A$12:$S$57, 16,FALSE) -> 2.77 | AC39: =W33 -> Yandle, Chuck | AD39: =IF(VLOOKUP(AC39,$W:$Z,2,FALSE)>=100, IF(VLOOKUP(AC39,$W:$Z,4,FALSE)>$AD$13, IF(VLOOKUP(AC39,$W:$Z,4,FALSE)>=$AD$13+0.5,3, IF(VLOOKUP(AC39,$W:$Z,4,FALSE)>=$AD$13+0.25,2,1) ), 0), 0) -> 1
A40: Miller, Taytem | D40: 23 | H40: 62 | L40: 672.67 | P40: 2.7 | S40: 29.25 | W40: Albert, Rowan | X40: =VLOOKUP(W40,$A$12:$S$57, 4,FALSE) -> 178 | Y40: =VLOOKUP(W40,$A$12:$S$57, 8,FALSE) -> 470 | Z40: =VLOOKUP(W40,$A$12:$S$57, 16,FALSE) -> 2.64 | AC40: =W34 -> Admin, AMC | AD40: =IF(VLOOKUP(AC40,$W:$Z,2,FALSE)>=100, IF(VLOOKUP(AC40,$W:$Z,4,FALSE)>$AD$13, IF(VLOOKUP(AC40,$W:$Z,4,FALSE)>=$AD$13+0.5,3, IF(VLOOKUP(AC40,$W:$Z,4,FALSE)>=$AD$13+0.25,2,1) ), 0), 0) -> 0
...

Sheet Week 3
A1: AMC | F1: Employee AweS.U.M. Report
A2: Woodinville Unit2449 (02449)
A3: 17640 138th Pl. NE
A4: Woodinville, Washington | F4: Business Date Range: 12/5/2025 to 12/11/2025
A5: 98072- | F5: Sort By Employee
A6: UNITED STATES
M7: Average | AC7: Team | AD7: UPT | AE7: n | AG7: Winner For the Week | AK7: Scoreboard
I8: UPT | M8: Transaction | W8: Chica | Y8: Average Tranaction | Z8: =(SUM(Y11:Y20)/SUM(X11:X20)) -> 2.5298507 | AC8: =W8 -> Chica | AD8: =Z8 -> 2.5298507 | AE8: =SUM(X11:X20) -> 402 | AG8: 1st | AH8: =INDEX($AC$8:$AC$12, MATCH(LARGE($AD$8:$AD$12, 1), $AD$8:$AD$12, 0)) -> Balloon Boy | AL8: Previous Week | AM8: Bonus Points (Individual) | AN8: Bonus Point Team Improvement | AO8: Earned Points | AP8: Total Points
G9: Theatre Average: | I9: 2.55 | O9: 24.48 | AC9: =W22 -> Bonnie | AD9: =Z22 -> 2.6206897 | AE9: =SUM(X25:X34) -> 522 | AG9: 2nd | AH9: =INDEX($AC$8:$AC$12, MATCH(LARGE($AD$8:$AD$12, 2), $AD$8:$AD$12, 0)) -> Bonnie | AK9: =W8 -> Chica | AL9: ='Week 2'!AP9 -> 11 | AM9: =AD28 -> 0 | AN9: =AH31 -> 0 | AO9: =AH14 -> 0 | AP9: =SUM(AL9:AO9) -> 11
D10: # of Transactions | X10: # Transactions | Y10: # of Units Sold | Z10: UPT | AC10: =W36 -> Freddy | AD10: =Z36 -> 2.5904437 | AE10: =SUM(X39:X48) -> 293 | AG10: 3rd | AH10: =INDEX($AC$8:$AC$12, MATCH(LARGE($AD$8:$AD$12, 3), $AD$8:$AD$12, 0)) -> Freddy | AK10: =W22 -> Bonnie | AL10: ='Week 2'!AP10 -> 4 | AM10: =AD41 -> 1 | AN10: =AH32 -> 0 | AO10: =AH15 -> 2 | AP10: =SUM(AL10:AO10) -> 7
A11: Employee Name | G11: # of Units Sold | K11: Total Sales | P11: UPT | S11: Average Transaction | W11: Lopez, Ebony | X11: =VLOOKUP(W11,$A$12:$S$54, 4,FALSE) -> 27 | Y11: =VLOOKUP(W11,$A$12:$S$54, 8,FALSE) -> 61 | Z11: =VLOOKUP(W11,$A$12:$S$54, 16,FALSE) -> 2.26 | AC11: =W50 -> Balloon Boy | AD11: =Z50 -> 2.6348588 | AE11: =SUM(X53:X62) -> 1027 | AK11: =W36 -> Freddy | AL11: ='Week 2'!AP11 -> 5 | AM11: =AD54 -> 2 | AN11: =AH33 -> 0 | AO11: =AH16 -> 1 | AP11: =SUM(AL11:AO11) -> 8
A12: Admin, AMC | D12: 0 | H12: 0 | L12: 0 | P12: 0 | S12: 0 | W12: Allen, Wren | X12: =VLOOKUP(W12,$A$12:$S$54, 4,FALSE) -> 0 | Y12: =VLOOKUP(W12,$A$12:$S$54, 8,FALSE) -> 0 | Z12: =VLOOKUP(W12,$A$12:$S$54, 16,FALSE) -> 0 | AC12: =W64 -> Foxy | AD12: =Z64 -> 2.3412698 | AE12: =SUM(X67:X75) -> 630 | AK12: =W50 -> Balloon Boy | AL12: ='Week 2'!AP12 -> 7 | AM12: =AD66 -> 2 | AN12: =AH34 -> 0 | AO12: =AH17 -> 3 | AP12: =SUM(AL12:AO12) -> 12
A13: admin2, amc | D13: 0 | H13: 0 | L13: 0 | P13: 0 | S13: 0 | W13: Araya, Kidane | X13: =VLOOKUP(W13,$A$12:$S$54, 4,FALSE) -> 147 | Y13: =VLOOKUP(W13,$A$12:$S$54, 8,FALSE) -> 353 | Z13: =VLOOKUP(W13,$A$12:$S$54, 16,FALSE) -> 2.4 | AC13: THEATRE | AD13: =I9 -> 2.55 | AE13: =SUM(D12:D56) -> 2874 | AG13: Earned Points Ranking | AK13: =W64 -> Foxy | AL13: ='Week 2'!AP13 -> 2 | AM13: =AD78 -> 0 | AN13: =AH35 -> 0 | AO13: =AH18 -> 0 | AP13: =SUM(AL13:AO13) -> 2
A14: Administrator, RSM | D14: 0 | H14: 0 | L14: 0 | P14: 0 | S14: 0 | W14: Gemmer, Jake | X14: =VLOOKUP(W14,$A$12:$S$54, 4,FALSE) -> 11 | Y14: =VLOOKUP(W14,$A$12:$S$54, 8,FALSE) -> 21 | Z14: =VLOOKUP(W14,$A$12:$S$54, 16,FALSE) -> 1.91 | AG14: =W8 -> Chica | AH14: =IF(AG14=$AH$8,3,IF(AG14=$AH$9,2,IF(AG14=$AH$10,1,0))) -> 0
A15: Albert, Rowan | D15: 64 | H15: 136 | L15: 1230.75 | P15: 2.13 | S15: 19.23 | W15: Jackson, Parker | X15: =VLOOKUP(W15,$A$12:$S$54, 4,FALSE) -> 85 | Y15: =VLOOKUP(W15,$A$12:$S$54, 8,FALSE) -> 249 | Z15: =VLOOKUP(W15,$A$12:$S$54, 16,FALSE) -> 2.93 | AG15: =W22 -> Bonnie | AH15: =IF(AG15=$AH$8,3,IF(AG15=$AH$9,2,IF(AG15=$AH$10,1,0))) -> 2 | AM15: Leaderboard
A16: Alemayehu, Eyouel | D16: 0 | H16: 0 | L16: 0 | P16: 0 | S16: 0 | W16: Mccarty, Katelynn | X16: =VLOOKUP(W16,$A$12:$S$54, 4,FALSE) -> 8 | Y16: =VLOOKUP(W16,$A$12:$S$54, 8,FALSE) -> 21 | Z16: =VLOOKUP(W16,$A$12:$S$54, 16,FALSE) -> 2.63 | AG16: =W36 -> Freddy | AH16: =IF(AG16=$AH$8,3,IF(AG16=$AH$9,2,IF(AG16=$AH$10,1,0))) -> 1 | AM16: First | AN16: =INDEX($AK$9:$AK$13, MATCH(LARGE($AP$9:$AP$13, 1), $AP$9:$AP$13, 0)) -> Balloon Boy
A17: Allen, Wren | D17: 0 | H17: 0 | L17: 0 | P17: 0 | S17: 0 | W17: Montero, Rowan | X17: =VLOOKUP(W17,$A$12:$S$54, 4,FALSE) -> 0 | Y17: =VLOOKUP(W17,$A$12:$S$54, 8,FALSE) -> 0 | Z17: =VLOOKUP(W17,$A$12:$S$54, 16,FALSE) -> 0 | AC17: =W8 -> Chica | AD17: Bonus Points? | AG17: =W50 -> Balloon Boy | AH17: =IF(AG17=$AH$8,3,IF(AG17=$AH$9,2,IF(AG17=$AH$10,1,0))) -> 3 | AM17: Second | AN17: =INDEX($AK$9:$AK$13, MATCH(LARGE($AP$9:$AP$13, 2), $AP$9:$AP$13, 0)) -> Chica
A18: Araya, Kidane | D18: 147 | H18: 353 | L18: 3850.68 | P18: 2.4 | S18: 26.2 | W18: Pepper, Courtney | X18: =VLOOKUP(W18,$A$12:$S$54, 4,FALSE) -> 124 | Y18: =VLOOKUP(W18,$A$12:$S$54, 8,FALSE) -> 312 | Z18: =VLOOKUP(W18,$A$12:$S$54, 16,FALSE) -> 2.52 | AC18: =W11 -> Lopez, Ebony | AD18: =IF(VLOOKUP(AC18,$W:$Z,2,FALSE)>=100, IF(VLOOKUP(AC18,$W:$Z,4,FALSE)>$AD$13, IF(VLOOKUP(AC18,$W:$Z,4,FALSE)>=$AD$13+0.5,3, IF(VLOOKUP(AC18,$W:$Z,4,FALSE)>=$AD$13+0.25,2,1) ), 0), 0) -> 0 | AG18: =W64 -> Foxy | AH18: =IF(AG18=$AH$8,3,IF(AG18=$AH$9,2,IF(AG18=$AH$10,1,0))) -> 0 | AM18: Third | AN18: =INDEX($AK$9:$AK$13, MATCH(LARGE($AP$9:$AP$13, 3), $AP$9:$AP$13, 0)) -> Freddy
A19: Cloud, Annette | D19: 0 | H19: 0 | L19: 0 | P19: 0 | S19: 0 | W19: Taylor, Ronni | X19: =VLOOKUP(W19,$A$12:$S$54, 4,FALSE) -> 0 | Y19: =VLOOKUP(W19,$A$12:$S$54, 8,FALSE) -> 0 | Z19: =VLOOKUP(W19,$A$12:$S$54, 16,FALSE) -> 0 | AC19: =W12 -> Allen, Wren | AD19: =IF(VLOOKUP(AC19,$W:$Z,2,FALSE)>=100, IF(VLOOKUP(AC19,$W:$Z,4,FALSE)>$AD$13, IF(VLOOKUP(AC19,$W:$Z,4,FALSE)>=$AD$13+0.5,3, IF(VLOOKUP(AC19,$W:$Z,4,FALSE)>=$AD$13+0.25,2,1) ), 0), 0) -> 0 | AM19: Fourth | AN19: =INDEX($AK$9:$AK$13, MATCH(LARGE($AP$9:$AP$13, 4), $AP$9:$AP$13, 0)) -> Bonnie
A20: DaPra, Kylan | D20: 93 | H20: 222 | L20: 2258.3 | P20: 2.39 | S20: 24.28 | V20: keira | W20: Admin, AMC | X20: =VLOOKUP(W20,$A$12:$S$54, 4,FALSE) -> 0 | Y20: =VLOOKUP(W20,$A$12:$S$54, 8,FALSE) -> 0 | Z20: =VLOOKUP(W20,$A$12:$S$54, 16,FALSE) -> 0 | AC20: =W13 -> Araya, Kidane | AD20: =IF(VLOOKUP(AC20,$W:$Z,2,FALSE)>=100, IF(VLOOKUP(AC20,$W:$Z,4,FALSE)>$AD$13, IF(VLOOKUP(AC20,$W:$Z,4,FALSE)>=$AD$13+0.5,3, IF(VLOOKUP(AC20,$W:$Z,4,FALSE)>=$AD$13+0.25,2,1) ), 0), 0) -> 0 | AM20: Fifth | AN20: =INDEX($AK$9:$AK$13, MATCH(LARGE($AP$9:$AP$13, 5), $AP$9:$AP$13, 0)) -> Foxy
A21: Delelu, Samra | D21: 0 | H21: 0 | L21: 0 | P21: 0 | S21: 0 | AC21: =W14 -> Gemmer, Jake | AD21: =IF(VLOOKUP(AC21,$W:$Z,2,FALSE)>=100, IF(VLOOKUP(AC21,$W:$Z,4,FALSE)>$AD$13, IF(VLOOKUP(AC21,$W:$Z,4,FALSE)>=$AD$13+0.5,3, IF(VLOOKUP(AC21,$W:$Z,4,FALSE)>=$AD$13+0.25,2,1) ), 0), 0) -> 0 | AG21: Last Week
A22: Dick, Emilie | D22: 71 | H22: 223 | L22: 1812.81 | P22: 3.14 | S22: 25.53 | W22: Bonnie | Y22: UPT | Z22: =(SUM(Y25:Y34)/SUM(X25:X34)) -> 2.6206897 | AC22: =W15 -> Jackson, Parker | AD22: =IF(VLOOKUP(AC22,$W:$Z,2,FALSE)>=100, IF(VLOOKUP(AC22,$W:$Z,4,FALSE)>$AD$13, IF(VLOOKUP(AC22,$W:$Z,4,FALSE)>=$AD$13+0.5,3, IF(VLOOKUP(AC22,$W:$Z,4,FALSE)>=$AD$13+0.25,2,1) ), 0), 0) -> 0 | AG22: Team | AH22: UPT
A23: Farmer, Kasey | D23: 41 | H23: 101 | L23: 896.15 | P23: 2.46 | S23: 21.86 | AC23: =W16 -> Mccarty, Katelynn | AD23: =IF(VLOOKUP(AC23,$W:$Z,2,FALSE)>=100, IF(VLOOKUP(AC23,$W:$Z,4,FALSE)>$AD$13, IF(VLOOKUP(AC23,$W:$Z,4,FALSE)>=$AD$13+0.5,3, IF(VLOOKUP(AC23,$W:$Z,4,FALSE)>=$AD$13+0.25,2,1) ), 0), 0) -> 0 | AG23: =W8 -> Chica | AH23: ='Week 2'!AD8 -> 2.7761468
A24: Findley, Amanda | D24: 0 | H24: 0 | L24: 0 | P24: 0 | S24: 0 | X24: # Transactions | Y24: # of Units Sold | Z24: UPT | AC24: =W17 -> Montero, Rowan | AD24: =IF(VLOOKUP(AC24,$W:$Z,2,FALSE)>=100, IF(VLOOKUP(AC24,$W:$Z,4,FALSE)>$AD$13, IF(VLOOKUP(AC24,$W:$Z,4,FALSE)>=$AD$13+0.5,3, IF(VLOOKUP(AC24,$W:$Z,4,FALSE)>=$AD$13+0.25,2,1) ), 0), 0) -> 0 | AG24: =W22 -> Bonnie | AH24: ='Week 2'!AD9 -> 2.7297297
A25: Gashu, Amanuel | D25: 0 | H25: 0 | L25: 0 | P25: 0 | S25: 0 | W25: Zeller, Daniel | X25: =VLOOKUP(W25,$A$12:$S$56, 4,FALSE) -> 48 | Y25: =VLOOKUP(W25,$A$12:$S$56, 8,FALSE) -> 123 | Z25: =VLOOKUP(W25,$A$12:$S$56, 16,FALSE) -> 2.56 | AC25: =W18 -> Pepper, Courtney | AD25: =IF(VLOOKUP(AC25,$W:$Z,2,FALSE)>=100, IF(VLOOKUP(AC25,$W:$Z,4,FALSE)>$AD$13, IF(VLOOKUP(AC25,$W:$Z,4,FALSE)>=$AD$13+0.5,3, IF(VLOOKUP(AC25,$W:$Z,4,FALSE)>=$AD$13+0.25,2,1) ), 0), 0) -> 0 | AG25: =W36 -> Freddy | AH25: ='Week 2'!AD10 -> 2.6085919
A26: Gemmer, Jake | D26: 11 | H26: 21 | L26: 196.49 | P26: 1.91 | S26: 17.86 | W26: Dick, Emilie | X26: =VLOOKUP(W26,$A$12:$S$56, 4,FALSE) -> 71 | Y26: =VLOOKUP(W26,$A$12:$S$56, 8,FALSE) -> 223 | Z26: =VLOOKUP(W26,$A$12:$S$56, 16,FALSE) -> 3.14 | AC26: =W19 -> Taylor, Ronni | AD26: =IF(VLOOKUP(AC26,$W:$Z,2,FALSE)>=100, IF(VLOOKUP(AC26,$W:$Z,4,FALSE)>$AD$13, IF(VLOOKUP(AC26,$W:$Z,4,FALSE)>=$AD$13+0.5,3, IF(VLOOKUP(AC26,$W:$Z,4,FALSE)>=$AD$13+0.25,2,1) ), 0), 0) -> 0 | AG26: =W50 -> Balloon Boy | AH26: ='Week 2'!AD11 -> 2.7127937
A27: Hatch, Aidan | D27: 49 | H27: 111 | L27: 970.35 | P27: 2.27 | S27: 19.8 | W27: Farmer, Kasey | X27: =VLOOKUP(W27,$A$12:$S$56, 4,FALSE) -> 41 | Y27: =VLOOKUP(W27,$A$12:$S$56, 8,FALSE) -> 101 | Z27: =VLOOKUP(W27,$A$12:$S$56, 16,FALSE) -> 2.46 | AC27: =W20 -> Admin, AMC | AD27: =IF(VLOOKUP(AC27,$W:$Z,2,FALSE)>=100, IF(VLOOKUP(AC27,$W:$Z,4,FALSE)>$AD$13, IF(VLOOKUP(AC27,$W:$Z,4,FALSE)>=$AD$13+0.5,3, IF(VLOOKUP(AC27,$W:$Z,4,FALSE)>=$AD$13+0.25,2,1) ), 0), 0) -> 0 | AG27: =W64 -> Foxy | AH27: ='Week 2'!AD12 -> 2.602
A28: Hill, Gabby | D28: 131 | H28: 393 | L28: 3708.73 | P28: 3 | S28: 28.31 | W28: Gashu, Amanuel | X28: =VLOOKUP(W28,$A$12:$S$56, 4,FALSE) -> 0 | Y28: =VLOOKUP(W28,$A$12:$S$56, 8,FALSE) -> 0 | Z28: =VLOOKUP(W28,$A$12:$S$56, 16,FALSE) -> 0 | AC28: Total Bonus | AD28: =SUM(AD18:AD27) -> 0
A29: Isreal, Zeal | D29: 409 | H29: 1085 | L29: 10873 | P29: 2.65 | S29: 26.59 | W29: Hatch, Aidan | X29: =VLOOKUP(W29,$A$12:$S$56, 4,FALSE) -> 49 | Y29: =VLOOKUP(W29,$A$12:$S$56, 8,FALSE) -> 111 | Z29: =VLOOKUP(W29,$A$12:$S$56, 16,FALSE) -> 2.27
A30: Jackson, Parker | D30: 85 | H30: 249 | L30: 2295.87 | P30: 2.93 | S30: 27.01 | W30: Miller, Taytem | X30: =VLOOKUP(W30,$A$12:$S$56, 4,FALSE) -> 65 | Y30: =VLOOKUP(W30,$A$12:$S$56, 8,FALSE) -> 172 | Z30: =VLOOKUP(W30,$A$12:$S$56, 16,FALSE) -> 2.65 | AC30: =W22 -> Bonnie | AD30: Bonus Points? | AG30: Bonus Point for Team Improvement?
A31: Kelly, Ryan | D31: 23 | H31: 153 | L31: 856.36 | P31: 6.65 | S31: 37.23 | W31: Ryder, Erin | X31: =VLOOKUP(W31,$A$12:$S$56, 4,FALSE) -> 126 | Y31: =VLOOKUP(W31,$A$12:$S$56, 8,FALSE) -> 337 | Z31: =VLOOKUP(W31,$A$12:$S$56, 16,FALSE) -> 2.67 | AC31: =W25 -> Zeller, Daniel | AD31: =IF(VLOOKUP(AC31,$W:$Z,2,FALSE)>=100, IF(VLOOKUP(AC31,$W:$Z,4,FALSE)>$AD$13, IF(VLOOKUP(AC31,$W:$Z,4,FALSE)>=$AD$13+0.5,3, IF(VLOOKUP(AC31,$W:$Z,4,FALSE)>=$AD$13+0.25,2,1) ), 0), 0) -> 0 | AG31: =W8 -> Chica | AH31: =IF(AD8>AH23,1,0) -> 0
A32: Koessler, Bayley | D32: 1 | H32: 2 | L32: 0 | P32: 2 | S32: 0 | W32: Yandle, Chuck | X32: =VLOOKUP(W32,$A$12:$S$56, 4,FALSE) -> 122 | Y32: =VLOOKUP(W32,$A$12:$S$56, 8,FALSE) -> 301 | Z32: =VLOOKUP(W32,$A$12:$S$56, 16,FALSE) -> 2.47 | AC32: =W26 -> Dick, Emilie | AD32: =IF(VLOOKUP(AC32,$W:$Z,2,FALSE)>=100, IF(VLOOKUP(AC32,$W:$Z,4,FALSE)>$AD$13, IF(VLOOKUP(AC32,$W:$Z,4,FALSE)>=$AD$13+0.5,3, IF(VLOOKUP(AC32,$W:$Z,4,FALSE)>=$AD$13+0.25,2,1) ), 0), 0) -> 0 | AG32: =W22 -> Bonnie | AH32: =IF(AD9>AH24, 1,0) -> 0
A33: Krause, Daniel | D33: 50 | H33: 99 | L33: 948.74 | P33: 1.98 | S33: 18.97 | W33: Admin, AMC | X33: =VLOOKUP(W33,$A$12:$S$56, 4,FALSE) -> 0 | Y33: =VLOOKUP(W33,$A$12:$S$56, 8,FALSE) -> 0 | Z33: =VLOOKUP(W33,$A$12:$S$56, 16,FALSE) -> 0 | AC33: =W27 -> Farmer, Kasey | AD33: =IF(VLOOKUP(AC33,$W:$Z,2,FALSE)>=100, IF(VLOOKUP(AC33,$W:$Z,4,FALSE)>$AD$13, IF(VLOOKUP(AC33,$W:$Z,4,FALSE)>=$AD$13+0.5,3, IF(VLOOKUP(AC33,$W:$Z,4,FALSE)>=$AD$13+0.25,2,1) ), 0), 0) -> 0 | AG33: =W36 -> Freddy | AH33: =IF(AD10>AH25, 1,0) -> 0
A34: Lawson, Nick | D34: 4 | H34: 6 | L34: 53.16 | P34: 1.5 | S34: 13.29 | V34: abby | W34: Admin, AMC | X34: =VLOOKUP(W34,$A$12:$S$56, 4,FALSE) -> 0 | Y34: =VLOOKUP(W34,$A$12:$S$56, 8,FALSE) -> 0 | Z34: =VLOOKUP(W34,$A$12:$S$56, 16,FALSE) -> 0 | AC34: =W28 -> Gashu, Amanuel | AD34: =IF(VLOOKUP(AC34,$W:$Z,2,FALSE)>=100, IF(VLOOKUP(AC34,$W:$Z,4,FALSE)>$AD$13, IF(VLOOKUP(AC34,$W:$Z,4,FALSE)>=$AD$13+0.5,3, IF(VLOOKUP(AC34,$W:$Z,4,FALSE)>=$AD$13+0.25,2,1) ), 0), 0) -> 0 | AG34: =W50 -> Balloon Boy | AH34: =IF(AD11>AH26, 1,0) -> 0
A35: Lingg, Beckett | D35: 0 | H35: 0 | L35: 0 | P35: 0 | S35: 0 | AC35: =W29 -> Hatch, Aidan | AD35: =IF(VLOOKUP(AC35,$W:$Z,2,FALSE)>=100, IF(VLOOKUP(AC35,$W:$Z,4,FALSE)>$AD$13, IF(VLOOKUP(AC35,$W:$Z,4,FALSE)>=$AD$13+0.5,3, IF(VLOOKUP(AC35,$W:$Z,4,FALSE)>=$AD$13+0.25,2,1) ), 0), 0) -> 0 | AG35: =W64 -> Foxy | AH35: =IF(AD12>AH27, 1,0) -> 0
A36: Lopez, Ebony | D36: 27 | H36: 61 | L36: 580.43 | P36: 2.26 | S36: 21.5 | W36: Freddy | Y36: UPT | Z36: =(SUM(Y39:Y48)/SUM(X39:X48)) -> 2.5904437 | AC36: =W30 -> Miller, Taytem | AD36: =IF(VLOOKUP(AC36,$W:$Z,2,FALSE)>=100, IF(VLOOKUP(AC36,$W:$Z,4,FALSE)>$AD$13, IF(VLOOKUP(AC36,$W:$Z,4,FALSE)>=$AD$13+0.5,3, IF(VLOOKUP(AC36,$W:$Z,4,FALSE)>=$AD$13+0.25,2,1) ), 0), 0) -> 0
A37: Lopez, Matthew | D37: 41 | H37: 109 | L37: 1008.73 | P37: 2.66 | S37: 24.6 | AC37: =W31 -> Ryder, Erin | AD37: =IF(VLOOKUP(AC37,$W:$Z,2,FALSE)>=100, IF(VLOOKUP(AC37,$W:$Z,4,FALSE)>$AD$13, IF(VLOOKUP(AC37,$W:$Z,4,FALSE)>=$AD$13+0.5,3, IF(VLOOKUP(AC37,$W:$Z,4,FALSE)>=$AD$13+0.25,2,1) ), 0), 0) -> 1
A38: Mccarty, Katelynn | D38: 8 | H38: 21 | L38: 192.5 | P38: 2.63 | S38: 24.06 | X38: # Transactions | Y38: # of Units Sold | Z38: UPT | AC38: =W32 -> Yandle, Chuck | AD38: =IF(VLOOKUP(AC38,$W:$Z,2,FALSE)>=100, IF(VLOOKUP(AC38,$W:$Z,4,FALSE)>$AD$13, IF(VLOOKUP(AC38,$W:$Z,4,FALSE)>=$AD$13+0.5,3, IF(VLOOKUP(AC38,$W:$Z,4,FALSE)>=$AD$13+0.25,2,1) ), 0), 0) -> 0
A39: McChesney, Jack | D39: 93 | H39: 221 | L39: 2104.66 | P39: 2.38 | S39: 22.63 | W39: DaPra, Kylan | X39: =VLOOKUP(W39,$A$12:$S$56, 4,FALSE) -> 93 | Y39: =VLOOKUP(W39,$A$12:$S$56, 8,FALSE) -> 222 | Z39: =VLOOKUP(W39,$A$12:$S$56, 16,FALSE) -> 2.39 | AC39: =W33 -> Admin, AMC | AD39: =IF(VLOOKUP(AC39,$W:$Z,2,FALSE)>=100, IF(VLOOKUP(AC39,$W:$Z,4,FALSE)>$AD$13, IF(VLOOKUP(AC39,$W:$Z,4,FALSE)>=$AD$13+0.5,3, IF(VLOOKUP(AC39,$W:$Z,4,FALSE)>=$AD$13+0.25,2,1) ), 0), 0) -> 0
A40: Miller, Taytem | D40: 65 | H40: 172 | L40: 1586.94 | P40: 2.65 | S40: 24.41 | W40: Albert, Rowan | X40: =VLOOKUP(W40,$A$12:$S$56, 4,FALSE) -> 64 | Y40: =VLOOKUP(W40,$A$12:$S$56, 8,FALSE) -> 136 | Z40: =VLOOKUP(W40,$A$12:$S$56, 16,FALSE) -> 2.13 | AC40: =W34 -> Admin, AMC | AD40: =IF(VLOOKUP(AC40,$W:$Z,2,FALSE)>=100, IF(VLOOKUP(AC40,$W:$Z,4,FALSE)>$AD$13, IF(VLOOKUP(AC40,$W:$Z,4,FALSE)>=$AD$13+0.5,3, IF(VLOOKUP(AC40,$W:$Z,4,FALSE)>=$AD$13+0.25,2,1) ), 0), 0) -> 0
...

Sheet Week 4
A1: AMC | F1: Employee AweS.U.M. Report
A2: Woodinville Unit2449 (02449)
A3: 17640 138th Pl. NE
A4: Woodinville, Washington | F4: Business Date Range: 12/12/2025 to 12/18/2025
A5: 98072- | F5: Sort By Employee
A6: UNITED STATES
M7: Average | AC7: Team | AD7: UPT | AE7: n | AG7: Winner For the Week | AK7: Scoreboard
I8: UPT | M8: Transaction | W8: Chica | Y8: Average Tranaction | Z8: =(SUM(Y11:Y20)/SUM(X11:X20)) -> 2.5349544 | AC8: =W8 -> Chica | AD8: =Z8 -> 2.5349544 | AE8: =SUM(X11:X20) -> 329 | AG8: 1st | AH8: =INDEX($AC$8:$AC$12, MATCH(LARGE($AD$8:$AD$12, 1), $AD$8:$AD$12, 0)) -> Freddy | AL8: Previous Week | AM8: Bonus Points (Individual) | AN8: Bonus Point Team Improvement | AO8: Earned Points | AP8: Total Points
G9: Theatre Average: | I9: 2.47 | O9: $22.81 | AC9: =W22 -> Bonnie | AD9: =Z22 -> 2.4912281 | AE9: =SUM(X25:X34) -> 342 | AG9: 2nd | AH9: =INDEX($AC$8:$AC$12, MATCH(LARGE($AD$8:$AD$12, 2), $AD$8:$AD$12, 0)) -> Chica | AK9: =W8 -> Chica | AL9: ='Week 3'!AP9 -> 11 | AM9: =AD28 -> 1 | AN9: =AH31 -> 0 | AO9: =AH14 -> 2 | AP9: =SUM(AL9:AO9) -> 14
D10: # of Transactions | X10: # Transactions | Y10: # of Units Sold | Z10: UPT | AC10: =W36 -> Freddy | AD10: =Z36 -> 2.5585586 | AE10: =SUM(X39:X48) -> 333 | AG10: 3rd | AH10: =INDEX($AC$8:$AC$12, MATCH(LARGE($AD$8:$AD$12, 3), $AD$8:$AD$12, 0)) -> Bonnie | AK10: =W22 -> Bonnie | AL10: ='Week 3'!AP10 -> 7 | AM10: =AD41 -> 2 | AN10: =AH32 -> 0 | AO10: =AH15 -> 1 | AP10: =SUM(AL10:AO10) -> 10
A11: Employee Name | G11: # of Units Sold | K11: Total Sales | P11: UPT | S11: Average Transaction | W11: Lopez, Ebony | X11: =VLOOKUP(W11,$A$12:$S$60, 4,FALSE) -> 105 | Y11: =VLOOKUP(W11,$A$12:$S$60, 8,FALSE) -> 281 | Z11: =VLOOKUP(W11,$A$12:$S$60, 16,FALSE) -> 2.68 | AC11: =W50 -> Balloon Boy | AD11: =Z50 -> 2.4479554 | AE11: =SUM(X53:X62) -> 538 | AK11: =W36 -> Freddy | AL11: ='Week 3'!AP11 -> 8 | AM11: =AD54 -> 1 | AN11: =AH33 -> 0 | AO11: =AH16 -> 3 | AP11: =SUM(AL11:AO11) -> 12
A12: Admin, AMC | D12: 0 | H12: 0 | L12: 0 | P12: 0 | S12: 0 | W12: Allen, Wren | X12: =VLOOKUP(W12,$A$12:$S$60, 4,FALSE) -> 0 | Y12: =VLOOKUP(W12,$A$12:$S$60, 8,FALSE) -> 0 | Z12: =VLOOKUP(W12,$A$12:$S$60, 16,FALSE) -> 0 | AC12: =W64 -> Foxy | AD12: =Z64 -> 2.4080944 | AE12: =SUM(X67:X75) -> 593 | AK12: =W50 -> Balloon Boy | AL12: ='Week 3'!AP12 -> 12 | AM12: =AD66 -> 1 | AN12: =AH34 -> 0 | AO12: =AH17 -> 0 | AP12: =SUM(AL12:AO12) -> 13
A13: admin2, amc | D13: 0 | H13: 0 | L13: 0 | P13: 0 | S13: 0 | W13: Araya, Kidane | X13: =VLOOKUP(W13,$A$12:$S$60, 4,FALSE) -> 172 | Y13: =VLOOKUP(W13,$A$12:$S$60, 8,FALSE) -> 424 | Z13: =VLOOKUP(W13,$A$12:$S$60, 16,FALSE) -> 2.47 | AC13: THEATRE | AD13: =I9 -> 2.47 | AE13: =SUM(D12:D60) -> 2135 | AG13: Earned Points Ranking | AK13: =W64 -> Foxy | AL13: ='Week 3'!AP13 -> 2 | AM13: =AD78 -> 1 | AN13: =AH35 -> 1 | AO13: =AH18 -> 0 | AP13: =SUM(AL13:AO13) -> 4
A14: Administrator, RSM | D14: 0 | H14: 0 | L14: 0 | P14: 0 | S14: 0 | W14: Gemmer, Jake | X14: =VLOOKUP(W14,$A$12:$S$60, 4,FALSE) -> 2 | Y14: =VLOOKUP(W14,$A$12:$S$60, 8,FALSE) -> 2 | Z14: =VLOOKUP(W14,$A$12:$S$60, 16,FALSE) -> 1 | AG14: =W8 -> Chica | AH14: =IF(AG14=$AH$8,3,IF(AG14=$AH$9,2,IF(AG14=$AH$10,1,0))) -> 2
A15: Albert, Rowan | D15: 88 | H15: 223 | L15: 1974.36 | P15: 2.53 | S15: 22.44 | W15: Jackson, Parker | X15: =VLOOKUP(W15,$A$12:$S$60, 4,FALSE) -> 0 | Y15: =VLOOKUP(W15,$A$12:$S$60, 8,FALSE) -> 0 | Z15: =VLOOKUP(W15,$A$12:$S$60, 16,FALSE) -> 0 | AG15: =W22 -> Bonnie | AH15: =IF(AG15=$AH$8,3,IF(AG15=$AH$9,2,IF(AG15=$AH$10,1,0))) -> 1 | AM15: Leaderboard | AO15: Points
A16: Alemayehu, Eyouel | D16: 79 | H16: 163 | L16: 1534.43 | P16: 2.06 | S16: 19.42 | W16: Mccarty, Katelynn | X16: =VLOOKUP(W16,$A$12:$S$60, 4,FALSE) -> 0 | Y16: =VLOOKUP(W16,$A$12:$S$60, 8,FALSE) -> 0 | Z16: =VLOOKUP(W16,$A$12:$S$60, 16,FALSE) -> 0 | AG16: =W36 -> Freddy | AH16: =IF(AG16=$AH$8,3,IF(AG16=$AH$9,2,IF(AG16=$AH$10,1,0))) -> 3 | AM16: First | AN16: =INDEX($AK$9:$AK$13, MATCH(LARGE($AP$9:$AP$13, 1), $AP$9:$AP$13, 0)) -> Chica | AO16: =VLOOKUP(AN16,$AK$9:$AP$13,6,FALSE) -> 14
A17: Allen, Wren | D17: 0 | H17: 0 | L17: 0 | P17: 0 | S17: 0 | W17: Montero, Rowan | X17: =VLOOKUP(W17,$A$12:$S$60, 4,FALSE) -> 6 | Y17: =VLOOKUP(W17,$A$12:$S$60, 8,FALSE) -> 12 | Z17: =VLOOKUP(W17,$A$12:$S$60, 16,FALSE) -> 2 | AC17: =W8 -> Chica | AD17: Bonus Points? | AG17: =W50 -> Balloon Boy | AH17: =IF(AG17=$AH$8,3,IF(AG17=$AH$9,2,IF(AG17=$AH$10,1,0))) -> 0 | AM17: Second | AN17: =INDEX($AK$9:$AK$13, MATCH(LARGE($AP$9:$AP$13, 2), $AP$9:$AP$13, 0)) -> Balloon Boy | AO17: =VLOOKUP(AN17,$AK$9:$AP$13,6,FALSE) -> 13
A18: Araya, Kidane | D18: 172 | H18: 424 | L18: 3827.72 | P18: 2.47 | S18: 22.25 | W18: Pepper, Courtney | X18: =VLOOKUP(W18,$A$12:$S$60, 4,FALSE) -> 25 | Y18: =VLOOKUP(W18,$A$12:$S$60, 8,FALSE) -> 62 | Z18: =VLOOKUP(W18,$A$12:$S$60, 16,FALSE) -> 2.48 | AC18: =W11 -> Lopez, Ebony | AD18: =IF(VLOOKUP(AC18,$W:$Z,2,FALSE)>=100, IF(VLOOKUP(AC18,$W:$Z,4,FALSE)>$AD$13, IF(VLOOKUP(AC18,$W:$Z,4,FALSE)>=$AD$13+0.5,3, IF(VLOOKUP(AC18,$W:$Z,4,FALSE)>=$AD$13+0.25,2,1) ), 0), 0) -> 1 | AG18: =W64 -> Foxy | AH18: =IF(AG18=$AH$8,3,IF(AG18=$AH$9,2,IF(AG18=$AH$10,1,0))) -> 0 | AM18: Third | AN18: =INDEX($AK$9:$AK$13, MATCH(LARGE($AP$9:$AP$13, 3), $AP$9:$AP$13, 0)) -> Freddy | AO18: =VLOOKUP(AN18,$AK$9:$AP$13,6,FALSE) -> 12
A19: Carpenter, Iris | D19: 84 | H19: 222 | L19: 2055.17 | P19: 2.64 | S19: 24.47 | W19: Taylor, Ronni | X19: =VLOOKUP(W19,$A$12:$S$60, 4,FALSE) -> 19 | Y19: =VLOOKUP(W19,$A$12:$S$60, 8,FALSE) -> 53 | Z19: =VLOOKUP(W19,$A$12:$S$60, 16,FALSE) -> 2.79 | AC19: =W12 -> Allen, Wren | AD19: =IF(VLOOKUP(AC19,$W:$Z,2,FALSE)>=100, IF(VLOOKUP(AC19,$W:$Z,4,FALSE)>$AD$13, IF(VLOOKUP(AC19,$W:$Z,4,FALSE)>=$AD$13+0.5,3, IF(VLOOKUP(AC19,$W:$Z,4,FALSE)>=$AD$13+0.25,2,1) ), 0), 0) -> 0 | AM19: Fourth | AN19: =INDEX($AK$9:$AK$13, MATCH(LARGE($AP$9:$AP$13, 4), $AP$9:$AP$13, 0)) -> Bonnie | AO19: =VLOOKUP(AN19,$AK$9:$AP$13,6,FALSE) -> 10
A20: Cloud, Annette | D20: 0 | H20: 0 | L20: 0 | P20: 0 | S20: 0 | V20: keira | W20: Admin, AMC | X20: =VLOOKUP(W20,$A$12:$S$60, 4,FALSE) -> 0 | Y20: =VLOOKUP(W20,$A$12:$S$60, 8,FALSE) -> 0 | Z20: =VLOOKUP(W20,$A$12:$S$60, 16,FALSE) -> 0 | AC20: =W13 -> Araya, Kidane | AD20: =IF(VLOOKUP(AC20,$W:$Z,2,FALSE)>=100, IF(VLOOKUP(AC20,$W:$Z,4,FALSE)>$AD$13, IF(VLOOKUP(AC20,$W:$Z,4,FALSE)>=$AD$13+0.5,3, IF(VLOOKUP(AC20,$W:$Z,4,FALSE)>=$AD$13+0.25,2,1) ), 0), 0) -> 0 | AM20: Fifth | AN20: =INDEX($AK$9:$AK$13, MATCH(LARGE($AP$9:$AP$13, 5), $AP$9:$AP$13, 0)) -> Foxy | AO20: =VLOOKUP(AN20,$AK$9:$AP$13,6,FALSE) -> 4
A21: DaPra, Kylan | D21: 40 | H21: 115 | L21: 1023.52 | P21: 2.88 | S21: 25.59 | AC21: =W14 -> Gemmer, Jake | AD21: =IF(VLOOKUP(AC21,$W:$Z,2,FALSE)>=100, IF(VLOOKUP(AC21,$W:$Z,4,FALSE)>$AD$13, IF(VLOOKUP(AC21,$W:$Z,4,FALSE)>=$AD$13+0.5,3, IF(VLOOKUP(AC21,$W:$Z,4,FALSE)>=$AD$13+0.25,2,1) ), 0), 0) -> 0 | AG21: Last Week
A22: Delelu, Samra | D22: 0 | H22: 0 | L22: 0 | P22: 0 | S22: 0 | W22: Bonnie | Y22: UPT | Z22: =(SUM(Y25:Y34)/SUM(X25:X34)) -> 2.4912281 | AC22: =W15 -> Jackson, Parker | AD22: =IF(VLOOKUP(AC22,$W:$Z,2,FALSE)>=100, IF(VLOOKUP(AC22,$W:$Z,4,FALSE)>$AD$13, IF(VLOOKUP(AC22,$W:$Z,4,FALSE)>=$AD$13+0.5,3, IF(VLOOKUP(AC22,$W:$Z,4,FALSE)>=$AD$13+0.25,2,1) ), 0), 0) -> 0 | AG22: Team | AH22: UPT
A23: Dick, Emilie | D23: 113 | H23: 312 | L23: 2815.87 | P23: 2.76 | S23: 24.92 | AC23: =W16 -> Mccarty, Katelynn | AD23: =IF(VLOOKUP(AC23,$W:$Z,2,FALSE)>=100, IF(VLOOKUP(AC23,$W:$Z,4,FALSE)>$AD$13, IF(VLOOKUP(AC23,$W:$Z,4,FALSE)>=$AD$13+0.5,3, IF(VLOOKUP(AC23,$W:$Z,4,FALSE)>=$AD$13+0.25,2,1) ), 0), 0) -> 0 | AG23: =W8 -> Chica | AH23: ='Week 3'!AD8 -> 2.5298507
A24: Farmer, Kasey | D24: 15 | H24: 36 | L24: 338.9 | P24: 2.4 | S24: 22.59 | X24: # Transactions | Y24: # of Units Sold | Z24: UPT | AC24: =W17 -> Montero, Rowan | AD24: =IF(VLOOKUP(AC24,$W:$Z,2,FALSE)>=100, IF(VLOOKUP(AC24,$W:$Z,4,FALSE)>$AD$13, IF(VLOOKUP(AC24,$W:$Z,4,FALSE)>=$AD$13+0.5,3, IF(VLOOKUP(AC24,$W:$Z,4,FALSE)>=$AD$13+0.25,2,1) ), 0), 0) -> 0 | AG24: =W22 -> Bonnie | AH24: ='Week 3'!AD9 -> 2.6206897
A25: Findley, Amanda | D25: 0 | H25: 0 | L25: 0 | P25: 0 | S25: 0 | W25: Zeller, Daniel | X25: =VLOOKUP(W25,$A$12:$S$60, 4,FALSE) -> 34 | Y25: =VLOOKUP(W25,$A$12:$S$60, 8,FALSE) -> 89 | Z25: =VLOOKUP(W25,$A$12:$S$60, 16,FALSE) -> 2.62 | AC25: =W18 -> Pepper, Courtney | AD25: =IF(VLOOKUP(AC25,$W:$Z,2,FALSE)>=100, IF(VLOOKUP(AC25,$W:$Z,4,FALSE)>$AD$13, IF(VLOOKUP(AC25,$W:$Z,4,FALSE)>=$AD$13+0.5,3, IF(VLOOKUP(AC25,$W:$Z,4,FALSE)>=$AD$13+0.25,2,1) ), 0), 0) -> 0 | AG25: =W36 -> Freddy | AH25: ='Week 3'!AD10 -> 2.5904437
A26: Gashu, Amanuel | D26: 0 | H26: 0 | L26: 0 | P26: 0 | S26: 0 | W26: Dick, Emilie | X26: =VLOOKUP(W26,$A$12:$S$60, 4,FALSE) -> 113 | Y26: =VLOOKUP(W26,$A$12:$S$60, 8,FALSE) -> 312 | Z26: =VLOOKUP(W26,$A$12:$S$60, 16,FALSE) -> 2.76 | AC26: =W19 -> Taylor, Ronni | AD26: =IF(VLOOKUP(AC26,$W:$Z,2,FALSE)>=100, IF(VLOOKUP(AC26,$W:$Z,4,FALSE)>$AD$13, IF(VLOOKUP(AC26,$W:$Z,4,FALSE)>=$AD$13+0.5,3, IF(VLOOKUP(AC26,$W:$Z,4,FALSE)>=$AD$13+0.25,2,1) ), 0), 0) -> 0 | AG26: =W50 -> Balloon Boy | AH26: ='Week 3'!AD11 -> 2.6348588
A27: Gemmer, Jake | D27: 2 | H27: 2 | L27: 17.6 | P27: 1 | S27: 8.8 | W27: Farmer, Kasey | X27: =VLOOKUP(W27,$A$12:$S$60, 4,FALSE) -> 15 | Y27: =VLOOKUP(W27,$A$12:$S$60, 8,FALSE) -> 36 | Z27: =VLOOKUP(W27,$A$12:$S$60, 16,FALSE) -> 2.4 | AC27: =W20 -> Admin, AMC | AD27: =IF(VLOOKUP(AC27,$W:$Z,2,FALSE)>=100, IF(VLOOKUP(AC27,$W:$Z,4,FALSE)>$AD$13, IF(VLOOKUP(AC27,$W:$Z,4,FALSE)>=$AD$13+0.5,3, IF(VLOOKUP(AC27,$W:$Z,4,FALSE)>=$AD$13+0.25,2,1) ), 0), 0) -> 0 | AG27: =W64 -> Foxy | AH27: ='Week 3'!AD12 -> 2.3412698
A28: Hatch, Aidan | D28: 90 | H28: 206 | L28: 1833.51 | P28: 2.29 | S28: 20.37 | W28: Gashu, Amanuel | X28: =VLOOKUP(W28,$A$12:$S$60, 4,FALSE) -> 0 | Y28: =VLOOKUP(W28,$A$12:$S$60, 8,FALSE) -> 0 | Z28: =VLOOKUP(W28,$A$12:$S$60, 16,FALSE) -> 0 | AC28: Total Bonus | AD28: =SUM(AD18:AD27) -> 1
A29: Hill, Gabby | D29: 69 | H29: 170 | L29: 1513.26 | P29: 2.46 | S29: 21.93 | W29: Hatch, Aidan | X29: =VLOOKUP(W29,$A$12:$S$60, 4,FALSE) -> 90 | Y29: =VLOOKUP(W29,$A$12:$S$60, 8,FALSE) -> 206 | Z29: =VLOOKUP(W29,$A$12:$S$60, 16,FALSE) -> 2.29
A30: Isreal, Zeal | D30: 88 | H30: 199 | L30: 1851.5 | P30: 2.26 | S30: 21.04 | W30: Admin, AMC | X30: =VLOOKUP(W30,$A$12:$S$60, 4,FALSE) -> 0 | Y30: =VLOOKUP(W30,$A$12:$S$60, 8,FALSE) -> 0 | Z30: =VLOOKUP(W30,$A$12:$S$60, 16,FALSE) -> 0 | AC30: =W22 -> Bonnie | AD30: Bonus Points? | AG30: Bonus Point for Team Improvement?
A31: Jackson, Parker | D31: 0 | H31: 0 | L31: 0 | P31: 0 | S31: 0 | W31: Ryder, Erin | X31: =VLOOKUP(W31,$A$12:$S$60, 4,FALSE) -> 1 | Y31: =VLOOKUP(W31,$A$12:$S$60, 8,FALSE) -> 4 | Z31: =VLOOKUP(W31,$A$12:$S$60, 16,FALSE) -> 4 | AC31: =W25 -> Zeller, Daniel | AD31: =IF(VLOOKUP(AC31,$W:$Z,2,FALSE)>=100, IF(VLOOKUP(AC31,$W:$Z,4,FALSE)>$AD$13, IF(VLOOKUP(AC31,$W:$Z,4,FALSE)>=$AD$13+0.5,3, IF(VLOOKUP(AC31,$W:$Z,4,FALSE)>=$AD$13+0.25,2,1) ), 0), 0) -> 0 | AG31: =W8 -> Chica | AH31: 0
A32: Kelly, Ryan | D32: 19 | H32: 40 | L32: 374.8 | P32: 2.11 | S32: 19.73 | W32: Yandle, Chuck | X32: =VLOOKUP(W32,$A$12:$S$60, 4,FALSE) -> 89 | Y32: =VLOOKUP(W32,$A$12:$S$60, 8,FALSE) -> 205 | Z32: =VLOOKUP(W32,$A$12:$S$60, 16,FALSE) -> 2.3 | AC32: =W26 -> Dick, Emilie | AD32: =IF(VLOOKUP(AC32,$W:$Z,2,FALSE)>=100, IF(VLOOKUP(AC32,$W:$Z,4,FALSE)>$AD$13, IF(VLOOKUP(AC32,$W:$Z,4,FALSE)>=$AD$13+0.5,3, IF(VLOOKUP(AC32,$W:$Z,4,FALSE)>=$AD$13+0.25,2,1) ), 0), 0) -> 2 | AG32: =W22 -> Bonnie | AH32: =IF(AD9>AH24, 1,0) -> 0
A33: Koessler, Bayley | D33: 0 | H33: 0 | L33: 0 | P33: 0 | S33: 0 | W33: Way, Abby | X33: =VLOOKUP(W33,$A$12:$S$60, 4,FALSE) -> 0 | Y33: =VLOOKUP(W33,$A$12:$S$60, 8,FALSE) -> 0 | Z33: =VLOOKUP(W33,$A$12:$S$60, 16,FALSE) -> 0 | AC33: =W27 -> Farmer, Kasey | AD33: =IF(VLOOKUP(AC33,$W:$Z,2,FALSE)>=100, IF(VLOOKUP(AC33,$W:$Z,4,FALSE)>$AD$13, IF(VLOOKUP(AC33,$W:$Z,4,FALSE)>=$AD$13+0.5,3, IF(VLOOKUP(AC33,$W:$Z,4,FALSE)>=$AD$13+0.25,2,1) ), 0), 0) -> 0 | AG33: =W36 -> Freddy | AH33: =IF(AD10>AH25, 1,0) -> 0
A34: Krause, Daniel | D34: 0 | H34: 0 | L34: 0 | P34: 0 | S34: 0 | V34: abby | W34: Admin, AMC | X34: =VLOOKUP(W34,$A$12:$S$60, 4,FALSE) -> 0 | Y34: =VLOOKUP(W34,$A$12:$S$60, 8,FALSE) -> 0 | Z34: =VLOOKUP(W34,$A$12:$S$60, 16,FALSE) -> 0 | AC34: =W28 -> Gashu, Amanuel | AD34: =IF(VLOOKUP(AC34,$W:$Z,2,FALSE)>=100, IF(VLOOKUP(AC34,$W:$Z,4,FALSE)>$AD$13, IF(VLOOKUP(AC34,$W:$Z,4,FALSE)>=$AD$13+0.5,3, IF(VLOOKUP(AC34,$W:$Z,4,FALSE)>=$AD$13+0.25,2,1) ), 0), 0) -> 0 | AG34: =W50 -> Balloon Boy | AH34: =IF(AD11>AH26, 1,0) -> 0
A35: Lawson, Nick | D35: 136 | H35: 344 | L35: 3494.98 | P35: 2.53 | S35: 25.7 | AC35: =W29 -> Hatch, Aidan | AD35: =IF(VLOOKUP(AC35,$W:$Z,2,FALSE)>=100, IF(VLOOKUP(AC35,$W:$Z,4,FALSE)>$AD$13, IF(VLOOKUP(AC35,$W:$Z,4,FALSE)>=$AD$13+0.5,3, IF(VLOOKUP(AC35,$W:$Z,4,FALSE)>=$AD$13+0.25,2,1) ), 0), 0) -> 0 | AG35: =W64 -> Foxy | AH35: =IF(AD12>AH27, 1,0) -> 1
A36: Lingg, Beckett | D36: 7 | H36: 15 | L36: 141.66 | P36: 2.14 | S36: 20.24 | W36: Freddy | Y36: UPT | Z36: =(SUM(Y39:Y48)/SUM(X39:X48)) -> 2.5585586 | AC36: =W30 -> Admin, AMC | AD36: =IF(VLOOKUP(AC36,$W:$Z,2,FALSE)>=100, IF(VLOOKUP(AC36,$W:$Z,4,FALSE)>$AD$13, IF(VLOOKUP(AC36,$W:$Z,4,FALSE)>=$AD$13+0.5,3, IF(VLOOKUP(AC36,$W:$Z,4,FALSE)>=$AD$13+0.25,2,1) ), 0), 0) -> 0
A37: Lopez, Ebony | D37: 105 | H37: 281 | L37: 2643.87 | P37: 2.68 | S37: 25.18 | AC37: =W31 -> Ryder, Erin | AD37: =IF(VLOOKUP(AC37,$W:$Z,2,FALSE)>=100, IF(VLOOKUP(AC37,$W:$Z,4,FALSE)>$AD$13, IF(VLOOKUP(AC37,$W:$Z,4,FALSE)>=$AD$13+0.5,3, IF(VLOOKUP(AC37,$W:$Z,4,FALSE)>=$AD$13+0.25,2,1) ), 0), 0) -> 0
A38: Lopez, Matthew | D38: 0 | H38: 0 | L38: 0 | P38: 0 | S38: 0 | X38: # Transactions | Y38: # of Units Sold | Z38: UPT | AC38: =W32 -> Yandle, Chuck | AD38: =IF(VLOOKUP(AC38,$W:$Z,2,FALSE)>=100, IF(VLOOKUP(AC38,$W:$Z,4,FALSE)>$AD$13, IF(VLOOKUP(AC38,$W:$Z,4,FALSE)>=$AD$13+0.5,3, IF(VLOOKUP(AC38,$W:$Z,4,FALSE)>=$AD$13+0.25,2,1) ), 0), 0) -> 0
A39: Mccarty, Katelynn | D39: 0 | H39: 0 | L39: 0 | P39: 0 | S39: 0 | W39: DaPra, Kylan | X39: =VLOOKUP(W39,$A$12:$S$60, 4,FALSE) -> 40 | Y39: =VLOOKUP(W39,$A$12:$S$60, 8,FALSE) -> 115 | Z39: =VLOOKUP(W39,$A$12:$S$60, 16,FALSE) -> 2.88 | AC39: =W33 -> Way, Abby | AD39: =IF(VLOOKUP(AC39,$W:$Z,2,FALSE)>=100, IF(VLOOKUP(AC39,$W:$Z,4,FALSE)>$AD$13, IF(VLOOKUP(AC39,$W:$Z,4,FALSE)>=$AD$13+0.5,3, IF(VLOOKUP(AC39,$W:$Z,4,FALSE)>=$AD$13+0.25,2,1) ), 0), 0) -> 0
A40: McChesney, Jack | D40: 43 | H40: 86 | L40: 800.7 | P40: 2 | S40: 18.62 | W40: Albert, Rowan | X40: =VLOOKUP(W40,$A$12:$S$60, 4,FALSE) -> 88 | Y40: =VLOOKUP(W40,$A$12:$S$60, 8,FALSE) -> 223 | Z40: =VLOOKUP(W40,$A$12:$S$60, 16,FALSE) -> 2.53 | AC40: =W34 -> Admin, AMC | AD40: =IF(VLOOKUP(AC40,$W:$Z,2,FALSE)>=100, IF(VLOOKUP(AC40,$W:$Z,4,FALSE)>$AD$13, IF(VLOOKUP(AC40,$W:$Z,4,FALSE)>=$AD$13+0.5,3, IF(VLOOKUP(AC40,$W:$Z,4,FALSE)>=$AD$13+0.25,2,1) ), 0), 0) -> 0
...

Sheet Week 5
A1: AMC | F1: Employee AweS.U.M. Report
A2: Woodinville Unit2449 (02449)
A3: 17640 138th Pl. NE
A4: Woodinville, Washington | F4: Business Date Range: 12/19/2025 to 12/25/2025
A5: 98072- | F5: Sort By Employee
A6: UNITED STATES
M7: Average | AC7: Team | AD7: UPT | AE7: n | AG7: Winner For the Week | AK7: Scoreboard
I8: UPT | M8: Transaction | W8: Chica | Y8: Average Tranaction | Z8: =(SUM(Y11:Y20)/SUM(X11:X20)) -> 2.7727718 | AC8: =W8 -> Chica | AD8: =Z8 -> 2.7727718 | AE8: =SUM(X11:X20) -> 1021 | AG8: 1st | AH8: =INDEX($AC$8:$AC$12, MATCH(LARGE($AD$8:$AD$12, 1), $AD$8:$AD$12, 0)) -> Bonnie | AL8: Previous Week | AM8: Bonus Points (Individual) | AN8: Bonus Point Team Improvement | AO8: Earned Points | AP8: Total Points
G9: Theatre Average: | I9: 2.74 | O9: $25.39 | AC9: =W22 -> Bonnie | AD9: =Z22 -> 2.8271186 | AE9: =SUM(X25:X34) -> 590 | AG9: 2nd | AH9: =INDEX($AC$8:$AC$12, MATCH(LARGE($AD$8:$AD$12, 2), $AD$8:$AD$12, 0)) -> Foxy | AK9: =W8 -> Chica | AL9: ='Week 4'!AP9 -> 14 | AM9: =AD28 -> 4 | AN9: =AH31 -> 1 | AO9: =AH14 -> 1 | AP9: =SUM(AL9:AO9) -> 20
D10: # of Transactions | X10: # Transactions | Y10: # of Units Sold | Z10: UPT | AC10: =W36 -> Freddy | AD10: =Z36 -> 2.6605081 | AE10: =SUM(X39:X48) -> 866 | AG10: 3rd | AH10: =INDEX($AC$8:$AC$12, MATCH(LARGE($AD$8:$AD$12, 3), $AD$8:$AD$12, 0)) -> Chica | AK10: =W22 -> Bonnie | AL10: ='Week 4'!AP10 -> 10 | AM10: =AD41 -> 2 | AN10: =AH32 -> 1 | AO10: =AH15 -> 3 | AP10: =SUM(AL10:AO10) -> 16
A11: Employee Name | G11: # of Units Sold | K11: Total Sales | P11: UPT | S11: Average Transaction | W11: Lopez, Ebony | X11: =VLOOKUP(W11,$A$12:$S$65, 4,FALSE) -> 167 | Y11: =VLOOKUP(W11,$A$12:$S$65, 8,FALSE) -> 525 | Z11: =VLOOKUP(W11,$A$12:$S$65, 16,FALSE) -> 3.14 | AC11: =W50 -> Balloon Boy | AD11: =Z50 -> 2.6596597 | AE11: =SUM(X53:X62) -> 999 | AK11: =W36 -> Freddy | AL11: ='Week 4'!AP11 -> 12 | AM11: =AD54 -> 1 | AN11: =AH33 -> 1 | AO11: =AH16 -> 0 | AP11: =SUM(AL11:AO11) -> 14
